2023-03-20 08:28:13,584 - apps - ERROR - Exception on /logger [GET]
Traceback (most recent call last):
  File "C:\Users\as222\flask_project1\venv\Lib\site-packages\flask\app.py", line 2528, in wsgi_app
    response = self.full_dispatch_request()
               ^^^^^^^^^^^^^^^^^^^^^^^^^^^^
  File "C:\Users\as222\flask_project1\venv\Lib\site-packages\flask\app.py", line 1825, in full_dispatch_request
    rv = self.handle_user_exception(e)
         ^^^^^^^^^^^^^^^^^^^^^^^^^^^^^
  File "C:\Users\as222\flask_project1\venv\Lib\site-packages\flask\app.py", line 1823, in full_dispatch_request
    rv = self.dispatch_request()
         ^^^^^^^^^^^^^^^^^^^^^^^
  File "C:\Users\as222\flask_project1\venv\Lib\site-packages\flask\app.py", line 1799, in dispatch_request
    return self.ensure_sync(self.view_functions[rule.endpoint])(**view_args)
           ^^^^^^^^^^^^^^^^^^^^^^^^^^^^^^^^^^^^^^^^^^^^^^^^^^^^^^^^^^^^^^^^^
  File "C:\Users\as222\flask_project2\router.py", line 170, in logger
    logger.debug('This is a debug message.')
    ^^^^^^^^^^^^
AttributeError: 'function' object has no attribute 'debug'
2023-03-20 08:30:11,553 - apps - DEBUG - This is a debug message.
2023-03-20 08:30:11,554 - apps - INFO - This is an info message.
2023-03-20 08:30:11,555 - apps - WARNING - This is a warning message.
2023-03-20 08:30:11,555 - apps - ERROR - This is an error message.
2023-03-20 08:30:11,556 - apps - CRITICAL - This is a critical message.
2023-03-20 08:30:48,533 - apps - DEBUG - This is a debug message.
2023-03-20 08:30:48,533 - apps - INFO - This is an info message.
2023-03-20 08:30:48,538 - apps - WARNING - This is a warning message.
2023-03-20 08:30:48,538 - apps - ERROR - This is an error message.
2023-03-20 08:30:48,540 - apps - CRITICAL - This is a critical message.
2023-03-20 08:30:50,027 - apps - DEBUG - This is a debug message.
2023-03-20 08:30:50,028 - apps - INFO - This is an info message.
2023-03-20 08:30:50,028 - apps - WARNING - This is a warning message.
2023-03-20 08:30:50,029 - apps - ERROR - This is an error message.
2023-03-20 08:30:50,029 - apps - CRITICAL - This is a critical message.
2023-03-20 09:35:10,894 - apps - ERROR - Exception on /photo_uploads [POST]
Traceback (most recent call last):
  File "C:\Users\as222\flask_project1\venv\Lib\site-packages\flask\app.py", line 2528, in wsgi_app
    response = self.full_dispatch_request()
               ^^^^^^^^^^^^^^^^^^^^^^^^^^^^
  File "C:\Users\as222\flask_project1\venv\Lib\site-packages\flask\app.py", line 1825, in full_dispatch_request
    rv = self.handle_user_exception(e)
         ^^^^^^^^^^^^^^^^^^^^^^^^^^^^^
  File "C:\Users\as222\flask_project1\venv\Lib\site-packages\flask\app.py", line 1823, in full_dispatch_request
    rv = self.dispatch_request()
         ^^^^^^^^^^^^^^^^^^^^^^^
  File "C:\Users\as222\flask_project1\venv\Lib\site-packages\flask\app.py", line 1799, in dispatch_request
    return self.ensure_sync(self.view_functions[rule.endpoint])(**view_args)
           ^^^^^^^^^^^^^^^^^^^^^^^^^^^^^^^^^^^^^^^^^^^^^^^^^^^^^^^^^^^^^^^^^
  File "C:\Users\as222\flask_project2\router.py", line 139, in upload_photos
    return views.Upload_photo()
           ^^^^^^^^^^^^^^^^^^^^
  File "C:\Users\as222\flask_project2\apps\views\user.py", line 142, in Upload_photo
    Image_path=photos.url(Filename)
               ^^^^^^^^^^^^^^^^^^^^
  File "C:\Users\as222\flask_project1\venv\Lib\site-packages\flask_uploads\flask_uploads.py", line 236, in url
    return url_for('_uploads.uploaded_file', setname=self.name,
           ^^^^^^^^^^^^^^^^^^^^^^^^^^^^^^^^^^^^^^^^^^^^^^^^^^^^
  File "C:\Users\as222\flask_project1\venv\Lib\site-packages\flask\helpers.py", line 256, in url_for
    return current_app.url_for(
           ^^^^^^^^^^^^^^^^^^^^
  File "C:\Users\as222\flask_project1\venv\Lib\site-packages\flask\app.py", line 2034, in url_for
    return self.handle_url_build_error(error, endpoint, values)
           ^^^^^^^^^^^^^^^^^^^^^^^^^^^^^^^^^^^^^^^^^^^^^^^^^^^^
  File "C:\Users\as222\flask_project1\venv\Lib\site-packages\flask\app.py", line 2023, in url_for
    rv = url_adapter.build(  # type: ignore[union-attr]
         ^^^^^^^^^^^^^^^^^^^^^^^^^^^^^^^^^^^^^^^^^^^^^^
  File "C:\Users\as222\flask_project1\venv\Lib\site-packages\werkzeug\routing\map.py", line 917, in build
    raise BuildError(endpoint, values, method, self)
werkzeug.routing.exceptions.BuildError: Could not build url for endpoint '_uploads.uploaded_file' with values ['filename', 'setname']. Did you mean 'upload_photos' instead?
2023-03-20 09:36:37,180 - apps - ERROR - Exception on /photo_uploads [POST]
Traceback (most recent call last):
  File "C:\Users\as222\flask_project1\venv\Lib\site-packages\flask\app.py", line 2528, in wsgi_app
    response = self.full_dispatch_request()
               ^^^^^^^^^^^^^^^^^^^^^^^^^^^^
  File "C:\Users\as222\flask_project1\venv\Lib\site-packages\flask\app.py", line 1825, in full_dispatch_request
    rv = self.handle_user_exception(e)
         ^^^^^^^^^^^^^^^^^^^^^^^^^^^^^
  File "C:\Users\as222\flask_project1\venv\Lib\site-packages\flask\app.py", line 1823, in full_dispatch_request
    rv = self.dispatch_request()
         ^^^^^^^^^^^^^^^^^^^^^^^
  File "C:\Users\as222\flask_project1\venv\Lib\site-packages\flask\app.py", line 1799, in dispatch_request
    return self.ensure_sync(self.view_functions[rule.endpoint])(**view_args)
           ^^^^^^^^^^^^^^^^^^^^^^^^^^^^^^^^^^^^^^^^^^^^^^^^^^^^^^^^^^^^^^^^^
  File "C:\Users\as222\flask_project2\router.py", line 139, in upload_photos
    return views.Upload_photo()
           ^^^^^^^^^^^^^^^^^^^^
  File "C:\Users\as222\flask_project2\apps\views\user.py", line 142, in Upload_photo
    Image_path=photos.url(Filename)
               ^^^^^^^^^^^^^^^^^^^^
  File "C:\Users\as222\flask_project1\venv\Lib\site-packages\flask_uploads\flask_uploads.py", line 236, in url
    return url_for('_uploads.uploaded_file', setname=self.name,
           ^^^^^^^^^^^^^^^^^^^^^^^^^^^^^^^^^^^^^^^^^^^^^^^^^^^^
  File "C:\Users\as222\flask_project1\venv\Lib\site-packages\flask\helpers.py", line 256, in url_for
    return current_app.url_for(
           ^^^^^^^^^^^^^^^^^^^^
  File "C:\Users\as222\flask_project1\venv\Lib\site-packages\flask\app.py", line 2034, in url_for
    return self.handle_url_build_error(error, endpoint, values)
           ^^^^^^^^^^^^^^^^^^^^^^^^^^^^^^^^^^^^^^^^^^^^^^^^^^^^
  File "C:\Users\as222\flask_project1\venv\Lib\site-packages\flask\app.py", line 2023, in url_for
    rv = url_adapter.build(  # type: ignore[union-attr]
         ^^^^^^^^^^^^^^^^^^^^^^^^^^^^^^^^^^^^^^^^^^^^^^
  File "C:\Users\as222\flask_project1\venv\Lib\site-packages\werkzeug\routing\map.py", line 917, in build
    raise BuildError(endpoint, values, method, self)
werkzeug.routing.exceptions.BuildError: Could not build url for endpoint '_uploads.uploaded_file' with values ['filename', 'setname']. Did you mean 'upload_photos' instead?
2023-03-20 09:37:17,957 - apps - ERROR - Exception on /photo_uploads [POST]
Traceback (most recent call last):
  File "C:\Users\as222\flask_project1\venv\Lib\site-packages\flask\app.py", line 2528, in wsgi_app
    response = self.full_dispatch_request()
               ^^^^^^^^^^^^^^^^^^^^^^^^^^^^
  File "C:\Users\as222\flask_project1\venv\Lib\site-packages\flask\app.py", line 1825, in full_dispatch_request
    rv = self.handle_user_exception(e)
         ^^^^^^^^^^^^^^^^^^^^^^^^^^^^^
  File "C:\Users\as222\flask_project1\venv\Lib\site-packages\flask\app.py", line 1823, in full_dispatch_request
    rv = self.dispatch_request()
         ^^^^^^^^^^^^^^^^^^^^^^^
  File "C:\Users\as222\flask_project1\venv\Lib\site-packages\flask\app.py", line 1799, in dispatch_request
    return self.ensure_sync(self.view_functions[rule.endpoint])(**view_args)
           ^^^^^^^^^^^^^^^^^^^^^^^^^^^^^^^^^^^^^^^^^^^^^^^^^^^^^^^^^^^^^^^^^
  File "C:\Users\as222\flask_project2\router.py", line 139, in upload_photos
    return views.Upload_photo()
           ^^^^^^^^^^^^^^^^^^^^
  File "C:\Users\as222\flask_project2\apps\views\user.py", line 142, in Upload_photo
    Image_path=photos.url(Filename)
               ^^^^^^^^^^^^^^^^^^^^
  File "C:\Users\as222\flask_project1\venv\Lib\site-packages\flask_uploads\flask_uploads.py", line 236, in url
    return url_for('_uploads.uploaded_file', setname=self.name,
           ^^^^^^^^^^^^^^^^^^^^^^^^^^^^^^^^^^^^^^^^^^^^^^^^^^^^
  File "C:\Users\as222\flask_project1\venv\Lib\site-packages\flask\helpers.py", line 256, in url_for
    return current_app.url_for(
           ^^^^^^^^^^^^^^^^^^^^
  File "C:\Users\as222\flask_project1\venv\Lib\site-packages\flask\app.py", line 2034, in url_for
    return self.handle_url_build_error(error, endpoint, values)
           ^^^^^^^^^^^^^^^^^^^^^^^^^^^^^^^^^^^^^^^^^^^^^^^^^^^^
  File "C:\Users\as222\flask_project1\venv\Lib\site-packages\flask\app.py", line 2023, in url_for
    rv = url_adapter.build(  # type: ignore[union-attr]
         ^^^^^^^^^^^^^^^^^^^^^^^^^^^^^^^^^^^^^^^^^^^^^^
  File "C:\Users\as222\flask_project1\venv\Lib\site-packages\werkzeug\routing\map.py", line 917, in build
    raise BuildError(endpoint, values, method, self)
werkzeug.routing.exceptions.BuildError: Could not build url for endpoint '_uploads.uploaded_file' with values ['filename', 'setname']. Did you mean 'upload_photos' instead?
2023-03-20 09:44:06,846 - apps - ERROR - Exception on /photo_uploads [POST]
Traceback (most recent call last):
  File "C:\Users\as222\flask_project1\venv\Lib\site-packages\flask\app.py", line 2528, in wsgi_app
    response = self.full_dispatch_request()
               ^^^^^^^^^^^^^^^^^^^^^^^^^^^^
  File "C:\Users\as222\flask_project1\venv\Lib\site-packages\flask\app.py", line 1825, in full_dispatch_request
    rv = self.handle_user_exception(e)
         ^^^^^^^^^^^^^^^^^^^^^^^^^^^^^
  File "C:\Users\as222\flask_project1\venv\Lib\site-packages\flask\app.py", line 1823, in full_dispatch_request
    rv = self.dispatch_request()
         ^^^^^^^^^^^^^^^^^^^^^^^
  File "C:\Users\as222\flask_project1\venv\Lib\site-packages\flask\app.py", line 1799, in dispatch_request
    return self.ensure_sync(self.view_functions[rule.endpoint])(**view_args)
           ^^^^^^^^^^^^^^^^^^^^^^^^^^^^^^^^^^^^^^^^^^^^^^^^^^^^^^^^^^^^^^^^^
  File "C:\Users\as222\flask_project2\router.py", line 139, in upload_photos
    return views.Upload_photo()
           ^^^^^^^^^^^^^^^^^^^^
  File "C:\Users\as222\flask_project2\apps\views\user.py", line 142, in Upload_photo
    Image_path=photos.url(Filename)
               ^^^^^^^^^^^^^^^^^^^^
  File "C:\Users\as222\flask_project1\venv\Lib\site-packages\flask_uploads\flask_uploads.py", line 236, in url
    return url_for('_uploads.uploaded_file', setname=self.name,
           ^^^^^^^^^^^^^^^^^^^^^^^^^^^^^^^^^^^^^^^^^^^^^^^^^^^^
  File "C:\Users\as222\flask_project1\venv\Lib\site-packages\flask\helpers.py", line 256, in url_for
    return current_app.url_for(
           ^^^^^^^^^^^^^^^^^^^^
  File "C:\Users\as222\flask_project1\venv\Lib\site-packages\flask\app.py", line 2034, in url_for
    return self.handle_url_build_error(error, endpoint, values)
           ^^^^^^^^^^^^^^^^^^^^^^^^^^^^^^^^^^^^^^^^^^^^^^^^^^^^
  File "C:\Users\as222\flask_project1\venv\Lib\site-packages\flask\app.py", line 2023, in url_for
    rv = url_adapter.build(  # type: ignore[union-attr]
         ^^^^^^^^^^^^^^^^^^^^^^^^^^^^^^^^^^^^^^^^^^^^^^
  File "C:\Users\as222\flask_project1\venv\Lib\site-packages\werkzeug\routing\map.py", line 917, in build
    raise BuildError(endpoint, values, method, self)
werkzeug.routing.exceptions.BuildError: Could not build url for endpoint '_uploads.uploaded_file' with values ['filename', 'setname']. Did you mean 'upload_photos' instead?
2023-03-20 09:56:25,493 - apps - ERROR - Exception on /photo_uploads [POST]
Traceback (most recent call last):
  File "C:\Users\as222\flask_project1\venv\Lib\site-packages\flask\app.py", line 2528, in wsgi_app
    response = self.full_dispatch_request()
               ^^^^^^^^^^^^^^^^^^^^^^^^^^^^
  File "C:\Users\as222\flask_project1\venv\Lib\site-packages\flask\app.py", line 1825, in full_dispatch_request
    rv = self.handle_user_exception(e)
         ^^^^^^^^^^^^^^^^^^^^^^^^^^^^^
  File "C:\Users\as222\flask_project1\venv\Lib\site-packages\flask\app.py", line 1823, in full_dispatch_request
    rv = self.dispatch_request()
         ^^^^^^^^^^^^^^^^^^^^^^^
  File "C:\Users\as222\flask_project1\venv\Lib\site-packages\flask\app.py", line 1799, in dispatch_request
    return self.ensure_sync(self.view_functions[rule.endpoint])(**view_args)
           ^^^^^^^^^^^^^^^^^^^^^^^^^^^^^^^^^^^^^^^^^^^^^^^^^^^^^^^^^^^^^^^^^
  File "C:\Users\as222\flask_project2\router.py", line 139, in upload_photos
    return views.Upload_photo()
           ^^^^^^^^^^^^^^^^^^^^
  File "C:\Users\as222\flask_project2\apps\views\user.py", line 142, in Upload_photo
    Image_path=photos.url(Filename)
               ^^^^^^^^^^^^^^^^^^^^
  File "C:\Users\as222\flask_project1\venv\Lib\site-packages\flask_uploads\flask_uploads.py", line 236, in url
    return url_for('_uploads.uploaded_file', setname=self.name,
           ^^^^^^^^^^^^^^^^^^^^^^^^^^^^^^^^^^^^^^^^^^^^^^^^^^^^
  File "C:\Users\as222\flask_project1\venv\Lib\site-packages\flask\helpers.py", line 256, in url_for
    return current_app.url_for(
           ^^^^^^^^^^^^^^^^^^^^
  File "C:\Users\as222\flask_project1\venv\Lib\site-packages\flask\app.py", line 2034, in url_for
    return self.handle_url_build_error(error, endpoint, values)
           ^^^^^^^^^^^^^^^^^^^^^^^^^^^^^^^^^^^^^^^^^^^^^^^^^^^^
  File "C:\Users\as222\flask_project1\venv\Lib\site-packages\flask\app.py", line 2023, in url_for
    rv = url_adapter.build(  # type: ignore[union-attr]
         ^^^^^^^^^^^^^^^^^^^^^^^^^^^^^^^^^^^^^^^^^^^^^^
  File "C:\Users\as222\flask_project1\venv\Lib\site-packages\werkzeug\routing\map.py", line 917, in build
    raise BuildError(endpoint, values, method, self)
werkzeug.routing.exceptions.BuildError: Could not build url for endpoint '_uploads.uploaded_file' with values ['filename', 'setname']. Did you mean 'upload_photos' instead?
2023-03-20 09:57:11,862 - apps - ERROR - Exception on /photo_uploads [POST]
Traceback (most recent call last):
  File "C:\Users\as222\flask_project1\venv\Lib\site-packages\flask\app.py", line 2528, in wsgi_app
    response = self.full_dispatch_request()
               ^^^^^^^^^^^^^^^^^^^^^^^^^^^^
  File "C:\Users\as222\flask_project1\venv\Lib\site-packages\flask\app.py", line 1825, in full_dispatch_request
    rv = self.handle_user_exception(e)
         ^^^^^^^^^^^^^^^^^^^^^^^^^^^^^
  File "C:\Users\as222\flask_project1\venv\Lib\site-packages\flask\app.py", line 1823, in full_dispatch_request
    rv = self.dispatch_request()
         ^^^^^^^^^^^^^^^^^^^^^^^
  File "C:\Users\as222\flask_project1\venv\Lib\site-packages\flask\app.py", line 1799, in dispatch_request
    return self.ensure_sync(self.view_functions[rule.endpoint])(**view_args)
           ^^^^^^^^^^^^^^^^^^^^^^^^^^^^^^^^^^^^^^^^^^^^^^^^^^^^^^^^^^^^^^^^^
  File "C:\Users\as222\flask_project2\router.py", line 139, in upload_photos
    return views.Upload_photo()
           ^^^^^^^^^^^^^^^^^^^^
  File "C:\Users\as222\flask_project2\apps\views\user.py", line 142, in Upload_photo
    Image_path=photos.url(Filename)
               ^^^^^^^^^^^^^^^^^^^^
  File "C:\Users\as222\flask_project1\venv\Lib\site-packages\flask_uploads\flask_uploads.py", line 236, in url
    return url_for('_uploads.uploaded_file', setname=self.name,
           ^^^^^^^^^^^^^^^^^^^^^^^^^^^^^^^^^^^^^^^^^^^^^^^^^^^^
  File "C:\Users\as222\flask_project1\venv\Lib\site-packages\flask\helpers.py", line 256, in url_for
    return current_app.url_for(
           ^^^^^^^^^^^^^^^^^^^^
  File "C:\Users\as222\flask_project1\venv\Lib\site-packages\flask\app.py", line 2034, in url_for
    return self.handle_url_build_error(error, endpoint, values)
           ^^^^^^^^^^^^^^^^^^^^^^^^^^^^^^^^^^^^^^^^^^^^^^^^^^^^
  File "C:\Users\as222\flask_project1\venv\Lib\site-packages\flask\app.py", line 2023, in url_for
    rv = url_adapter.build(  # type: ignore[union-attr]
         ^^^^^^^^^^^^^^^^^^^^^^^^^^^^^^^^^^^^^^^^^^^^^^
  File "C:\Users\as222\flask_project1\venv\Lib\site-packages\werkzeug\routing\map.py", line 917, in build
    raise BuildError(endpoint, values, method, self)
werkzeug.routing.exceptions.BuildError: Could not build url for endpoint '_uploads.uploaded_file' with values ['filename', 'setname']. Did you mean 'upload_photos' instead?
2023-03-20 12:48:59,005 - apps - ERROR - Exception on /photo_uploads [POST]
Traceback (most recent call last):
  File "C:\Users\as222\flask_project1\venv\Lib\site-packages\flask\app.py", line 2528, in wsgi_app
    response = self.full_dispatch_request()
               ^^^^^^^^^^^^^^^^^^^^^^^^^^^^
  File "C:\Users\as222\flask_project1\venv\Lib\site-packages\flask\app.py", line 1825, in full_dispatch_request
    rv = self.handle_user_exception(e)
         ^^^^^^^^^^^^^^^^^^^^^^^^^^^^^
  File "C:\Users\as222\flask_project1\venv\Lib\site-packages\flask\app.py", line 1823, in full_dispatch_request
    rv = self.dispatch_request()
         ^^^^^^^^^^^^^^^^^^^^^^^
  File "C:\Users\as222\flask_project1\venv\Lib\site-packages\flask\app.py", line 1799, in dispatch_request
    return self.ensure_sync(self.view_functions[rule.endpoint])(**view_args)
           ^^^^^^^^^^^^^^^^^^^^^^^^^^^^^^^^^^^^^^^^^^^^^^^^^^^^^^^^^^^^^^^^^
  File "C:\Users\as222\flask_project2\router.py", line 139, in upload_photos
    return views.Upload_photo()
           ^^^^^^^^^^^^^^^^^^^^
  File "C:\Users\as222\flask_project2\apps\views\user.py", line 142, in Upload_photo
    Image_path=photos.url(Filename)
               ^^^^^^^^^^^^^^^^^^^^
  File "C:\Users\as222\flask_project1\venv\Lib\site-packages\flask_uploads\flask_uploads.py", line 236, in url
    return url_for('_uploads.uploaded_file', setname=self.name,
           ^^^^^^^^^^^^^^^^^^^^^^^^^^^^^^^^^^^^^^^^^^^^^^^^^^^^
  File "C:\Users\as222\flask_project1\venv\Lib\site-packages\flask\helpers.py", line 256, in url_for
    return current_app.url_for(
           ^^^^^^^^^^^^^^^^^^^^
  File "C:\Users\as222\flask_project1\venv\Lib\site-packages\flask\app.py", line 2034, in url_for
    return self.handle_url_build_error(error, endpoint, values)
           ^^^^^^^^^^^^^^^^^^^^^^^^^^^^^^^^^^^^^^^^^^^^^^^^^^^^
  File "C:\Users\as222\flask_project1\venv\Lib\site-packages\flask\app.py", line 2023, in url_for
    rv = url_adapter.build(  # type: ignore[union-attr]
         ^^^^^^^^^^^^^^^^^^^^^^^^^^^^^^^^^^^^^^^^^^^^^^
  File "C:\Users\as222\flask_project1\venv\Lib\site-packages\werkzeug\routing\map.py", line 917, in build
    raise BuildError(endpoint, values, method, self)
werkzeug.routing.exceptions.BuildError: Could not build url for endpoint '_uploads.uploaded_file' with values ['filename', 'setname']. Did you mean 'upload_photos' instead?
2023-03-20 14:44:21,181 - apps - ERROR - Exception on /photo_uploads [POST]
Traceback (most recent call last):
  File "C:\Users\as222\flask_project1\venv\Lib\site-packages\flask\app.py", line 2528, in wsgi_app
    response = self.full_dispatch_request()
               ^^^^^^^^^^^^^^^^^^^^^^^^^^^^
  File "C:\Users\as222\flask_project1\venv\Lib\site-packages\flask\app.py", line 1825, in full_dispatch_request
    rv = self.handle_user_exception(e)
         ^^^^^^^^^^^^^^^^^^^^^^^^^^^^^
  File "C:\Users\as222\flask_project1\venv\Lib\site-packages\flask\app.py", line 1823, in full_dispatch_request
    rv = self.dispatch_request()
         ^^^^^^^^^^^^^^^^^^^^^^^
  File "C:\Users\as222\flask_project1\venv\Lib\site-packages\flask\app.py", line 1799, in dispatch_request
    return self.ensure_sync(self.view_functions[rule.endpoint])(**view_args)
           ^^^^^^^^^^^^^^^^^^^^^^^^^^^^^^^^^^^^^^^^^^^^^^^^^^^^^^^^^^^^^^^^^
  File "C:\Users\as222\flask_project2\router.py", line 139, in upload_photos
    return views.Upload_photo()
           ^^^^^^^^^^^^^^^^^^^^
  File "C:\Users\as222\flask_project2\apps\views\user.py", line 141, in Upload_photo
    Image_path=photos.url(Filename)
               ^^^^^^^^^^^^^^^^^^^^
  File "C:\Users\as222\flask_project1\venv\Lib\site-packages\flask_uploads\flask_uploads.py", line 236, in url
    return url_for('_uploads.uploaded_file', setname=self.name,
           ^^^^^^^^^^^^^^^^^^^^^^^^^^^^^^^^^^^^^^^^^^^^^^^^^^^^
  File "C:\Users\as222\flask_project1\venv\Lib\site-packages\flask\helpers.py", line 256, in url_for
    return current_app.url_for(
           ^^^^^^^^^^^^^^^^^^^^
  File "C:\Users\as222\flask_project1\venv\Lib\site-packages\flask\app.py", line 2034, in url_for
    return self.handle_url_build_error(error, endpoint, values)
           ^^^^^^^^^^^^^^^^^^^^^^^^^^^^^^^^^^^^^^^^^^^^^^^^^^^^
  File "C:\Users\as222\flask_project1\venv\Lib\site-packages\flask\app.py", line 2023, in url_for
    rv = url_adapter.build(  # type: ignore[union-attr]
         ^^^^^^^^^^^^^^^^^^^^^^^^^^^^^^^^^^^^^^^^^^^^^^
  File "C:\Users\as222\flask_project1\venv\Lib\site-packages\werkzeug\routing\map.py", line 917, in build
    raise BuildError(endpoint, values, method, self)
werkzeug.routing.exceptions.BuildError: Could not build url for endpoint '_uploads.uploaded_file' with values ['filename', 'setname']. Did you mean 'upload_photos' instead?
2023-03-20 14:59:12,154 - apps - ERROR - Exception on /photo_uploads [POST]
Traceback (most recent call last):
  File "C:\Users\as222\flask_project1\venv\Lib\site-packages\flask\app.py", line 2528, in wsgi_app
    response = self.full_dispatch_request()
               ^^^^^^^^^^^^^^^^^^^^^^^^^^^^
  File "C:\Users\as222\flask_project1\venv\Lib\site-packages\flask\app.py", line 1825, in full_dispatch_request
    rv = self.handle_user_exception(e)
         ^^^^^^^^^^^^^^^^^^^^^^^^^^^^^
  File "C:\Users\as222\flask_project1\venv\Lib\site-packages\flask\app.py", line 1823, in full_dispatch_request
    rv = self.dispatch_request()
         ^^^^^^^^^^^^^^^^^^^^^^^
  File "C:\Users\as222\flask_project1\venv\Lib\site-packages\flask\app.py", line 1799, in dispatch_request
    return self.ensure_sync(self.view_functions[rule.endpoint])(**view_args)
           ^^^^^^^^^^^^^^^^^^^^^^^^^^^^^^^^^^^^^^^^^^^^^^^^^^^^^^^^^^^^^^^^^
  File "C:\Users\as222\flask_project2\router.py", line 139, in upload_photos
    return views.Upload_photo()
           ^^^^^^^^^^^^^^^^^^^^
  File "C:\Users\as222\flask_project2\apps\views\user.py", line 140, in Upload_photo
    Image_path=photos.url(Filename)
               ^^^^^^^^^^^^^^^^^^^^
  File "C:\Users\as222\flask_project1\venv\Lib\site-packages\flask_uploads\flask_uploads.py", line 236, in url
    return url_for('_uploads.uploaded_file', setname=self.name,
           ^^^^^^^^^^^^^^^^^^^^^^^^^^^^^^^^^^^^^^^^^^^^^^^^^^^^
  File "C:\Users\as222\flask_project1\venv\Lib\site-packages\flask\helpers.py", line 256, in url_for
    return current_app.url_for(
           ^^^^^^^^^^^^^^^^^^^^
  File "C:\Users\as222\flask_project1\venv\Lib\site-packages\flask\app.py", line 2034, in url_for
    return self.handle_url_build_error(error, endpoint, values)
           ^^^^^^^^^^^^^^^^^^^^^^^^^^^^^^^^^^^^^^^^^^^^^^^^^^^^
  File "C:\Users\as222\flask_project1\venv\Lib\site-packages\flask\app.py", line 2023, in url_for
    rv = url_adapter.build(  # type: ignore[union-attr]
         ^^^^^^^^^^^^^^^^^^^^^^^^^^^^^^^^^^^^^^^^^^^^^^
  File "C:\Users\as222\flask_project1\venv\Lib\site-packages\werkzeug\routing\map.py", line 917, in build
    raise BuildError(endpoint, values, method, self)
werkzeug.routing.exceptions.BuildError: Could not build url for endpoint '_uploads.uploaded_file' with values ['filename', 'setname']. Did you mean 'upload_photos' instead?
2023-03-20 19:20:41,197 - apps - ERROR - Exception on /photo_uploads [POST]
Traceback (most recent call last):
  File "C:\Users\as222\flask_project1\venv\Lib\site-packages\flask\app.py", line 2528, in wsgi_app
    response = self.full_dispatch_request()
               ^^^^^^^^^^^^^^^^^^^^^^^^^^^^
  File "C:\Users\as222\flask_project1\venv\Lib\site-packages\flask\app.py", line 1825, in full_dispatch_request
    rv = self.handle_user_exception(e)
         ^^^^^^^^^^^^^^^^^^^^^^^^^^^^^
  File "C:\Users\as222\flask_project1\venv\Lib\site-packages\flask\app.py", line 1823, in full_dispatch_request
    rv = self.dispatch_request()
         ^^^^^^^^^^^^^^^^^^^^^^^
  File "C:\Users\as222\flask_project1\venv\Lib\site-packages\flask\app.py", line 1799, in dispatch_request
    return self.ensure_sync(self.view_functions[rule.endpoint])(**view_args)
           ^^^^^^^^^^^^^^^^^^^^^^^^^^^^^^^^^^^^^^^^^^^^^^^^^^^^^^^^^^^^^^^^^
  File "C:\Users\as222\flask_project2\router.py", line 139, in upload_photos
    return views.Upload_photo()
           ^^^^^^^^^^^^^^^^^^^^
  File "C:\Users\as222\flask_project2\apps\views\user.py", line 140, in Upload_photo
    Image_path=images.url(Filename)
               ^^^^^^^^^^^^^^^^^^^^
  File "C:\Users\as222\flask_project1\venv\Lib\site-packages\flask_uploads\flask_uploads.py", line 236, in url
    return url_for('_uploads.uploaded_file', setname=self.name,
           ^^^^^^^^^^^^^^^^^^^^^^^^^^^^^^^^^^^^^^^^^^^^^^^^^^^^
  File "C:\Users\as222\flask_project1\venv\Lib\site-packages\flask\helpers.py", line 256, in url_for
    return current_app.url_for(
           ^^^^^^^^^^^^^^^^^^^^
  File "C:\Users\as222\flask_project1\venv\Lib\site-packages\flask\app.py", line 2034, in url_for
    return self.handle_url_build_error(error, endpoint, values)
           ^^^^^^^^^^^^^^^^^^^^^^^^^^^^^^^^^^^^^^^^^^^^^^^^^^^^
  File "C:\Users\as222\flask_project1\venv\Lib\site-packages\flask\app.py", line 2023, in url_for
    rv = url_adapter.build(  # type: ignore[union-attr]
         ^^^^^^^^^^^^^^^^^^^^^^^^^^^^^^^^^^^^^^^^^^^^^^
  File "C:\Users\as222\flask_project1\venv\Lib\site-packages\werkzeug\routing\map.py", line 917, in build
    raise BuildError(endpoint, values, method, self)
werkzeug.routing.exceptions.BuildError: Could not build url for endpoint '_uploads.uploaded_file' with values ['filename', 'setname']. Did you mean 'upload_photos' instead?
2023-03-20 19:35:28,211 - apps - ERROR - Exception on /photo_uploads [POST]
Traceback (most recent call last):
  File "C:\Users\as222\flask_project1\venv\Lib\site-packages\flask\app.py", line 2528, in wsgi_app
    response = self.full_dispatch_request()
               ^^^^^^^^^^^^^^^^^^^^^^^^^^^^
  File "C:\Users\as222\flask_project1\venv\Lib\site-packages\flask\app.py", line 1825, in full_dispatch_request
    rv = self.handle_user_exception(e)
         ^^^^^^^^^^^^^^^^^^^^^^^^^^^^^
  File "C:\Users\as222\flask_project1\venv\Lib\site-packages\flask\app.py", line 1823, in full_dispatch_request
    rv = self.dispatch_request()
         ^^^^^^^^^^^^^^^^^^^^^^^
  File "C:\Users\as222\flask_project1\venv\Lib\site-packages\flask\app.py", line 1799, in dispatch_request
    return self.ensure_sync(self.view_functions[rule.endpoint])(**view_args)
           ^^^^^^^^^^^^^^^^^^^^^^^^^^^^^^^^^^^^^^^^^^^^^^^^^^^^^^^^^^^^^^^^^
  File "C:\Users\as222\flask_project2\router.py", line 139, in upload_photos
    return views.Upload_photo()
           ^^^^^^^^^^^^^^^^^^^^
  File "C:\Users\as222\flask_project2\apps\views\user.py", line 140, in Upload_photo
    Image_path=images.url(Filename)
               ^^^^^^^^^^^^^^^^^^^^
  File "C:\Users\as222\flask_project1\venv\Lib\site-packages\flask_uploads\flask_uploads.py", line 236, in url
    return url_for('_uploads.uploaded_file', setname=self.name,
           ^^^^^^^^^^^^^^^^^^^^^^^^^^^^^^^^^^^^^^^^^^^^^^^^^^^^
  File "C:\Users\as222\flask_project1\venv\Lib\site-packages\flask\helpers.py", line 256, in url_for
    return current_app.url_for(
           ^^^^^^^^^^^^^^^^^^^^
  File "C:\Users\as222\flask_project1\venv\Lib\site-packages\flask\app.py", line 2034, in url_for
    return self.handle_url_build_error(error, endpoint, values)
           ^^^^^^^^^^^^^^^^^^^^^^^^^^^^^^^^^^^^^^^^^^^^^^^^^^^^
  File "C:\Users\as222\flask_project1\venv\Lib\site-packages\flask\app.py", line 2023, in url_for
    rv = url_adapter.build(  # type: ignore[union-attr]
         ^^^^^^^^^^^^^^^^^^^^^^^^^^^^^^^^^^^^^^^^^^^^^^
  File "C:\Users\as222\flask_project1\venv\Lib\site-packages\werkzeug\routing\map.py", line 917, in build
    raise BuildError(endpoint, values, method, self)
werkzeug.routing.exceptions.BuildError: Could not build url for endpoint '_uploads.uploaded_file' with values ['filename', 'setname']. Did you mean 'uploaded_photos' instead?
2023-03-20 21:40:24,041 - apps - ERROR - Exception on /photo_uploads [POST]
Traceback (most recent call last):
  File "C:\Users\as222\flask_project1\venv\Lib\site-packages\flask\app.py", line 2528, in wsgi_app
    response = self.full_dispatch_request()
               ^^^^^^^^^^^^^^^^^^^^^^^^^^^^
  File "C:\Users\as222\flask_project1\venv\Lib\site-packages\flask\app.py", line 1825, in full_dispatch_request
    rv = self.handle_user_exception(e)
         ^^^^^^^^^^^^^^^^^^^^^^^^^^^^^
  File "C:\Users\as222\flask_project1\venv\Lib\site-packages\flask\app.py", line 1823, in full_dispatch_request
    rv = self.dispatch_request()
         ^^^^^^^^^^^^^^^^^^^^^^^
  File "C:\Users\as222\flask_project1\venv\Lib\site-packages\flask\app.py", line 1799, in dispatch_request
    return self.ensure_sync(self.view_functions[rule.endpoint])(**view_args)
           ^^^^^^^^^^^^^^^^^^^^^^^^^^^^^^^^^^^^^^^^^^^^^^^^^^^^^^^^^^^^^^^^^
  File "C:\Users\as222\flask_project2\router.py", line 139, in upload_photos
    return views.Upload_photo()
           ^^^^^^^^^^^^^^^^^^^^
  File "C:\Users\as222\flask_project2\apps\views\user.py", line 159, in Upload_photo
    photo.save(os.path.join(app.config['UPLOAD_FOLDER'],Filename))
  File "C:\Users\as222\flask_project1\venv\Lib\site-packages\werkzeug\datastructures.py", line 3002, in save
    dst = open(dst, "wb")
          ^^^^^^^^^^^^^^^
FileNotFoundError: [Errno 2] No such file or directory: 'static/image/upload\\post.jpg'
2023-03-20 21:41:37,277 - apps - ERROR - Exception on /photo_uploads [POST]
Traceback (most recent call last):
  File "C:\Users\as222\flask_project1\venv\Lib\site-packages\flask\app.py", line 2528, in wsgi_app
    response = self.full_dispatch_request()
               ^^^^^^^^^^^^^^^^^^^^^^^^^^^^
  File "C:\Users\as222\flask_project1\venv\Lib\site-packages\flask\app.py", line 1825, in full_dispatch_request
    rv = self.handle_user_exception(e)
         ^^^^^^^^^^^^^^^^^^^^^^^^^^^^^
  File "C:\Users\as222\flask_project1\venv\Lib\site-packages\flask\app.py", line 1823, in full_dispatch_request
    rv = self.dispatch_request()
         ^^^^^^^^^^^^^^^^^^^^^^^
  File "C:\Users\as222\flask_project1\venv\Lib\site-packages\flask\app.py", line 1799, in dispatch_request
    return self.ensure_sync(self.view_functions[rule.endpoint])(**view_args)
           ^^^^^^^^^^^^^^^^^^^^^^^^^^^^^^^^^^^^^^^^^^^^^^^^^^^^^^^^^^^^^^^^^
  File "C:\Users\as222\flask_project2\router.py", line 139, in upload_photos
    return views.Upload_photo()
           ^^^^^^^^^^^^^^^^^^^^
  File "C:\Users\as222\flask_project2\apps\views\user.py", line 164, in Upload_photo
    Image_path=url_for('view_photo',photo_id=photo.id)
               ^^^^^^^^^^^^^^^^^^^^^^^^^^^^^^^^^^^^^^^
  File "C:\Users\as222\flask_project1\venv\Lib\site-packages\flask\helpers.py", line 256, in url_for
    return current_app.url_for(
           ^^^^^^^^^^^^^^^^^^^^
  File "C:\Users\as222\flask_project1\venv\Lib\site-packages\flask\app.py", line 2034, in url_for
    return self.handle_url_build_error(error, endpoint, values)
           ^^^^^^^^^^^^^^^^^^^^^^^^^^^^^^^^^^^^^^^^^^^^^^^^^^^^
  File "C:\Users\as222\flask_project1\venv\Lib\site-packages\flask\app.py", line 2023, in url_for
    rv = url_adapter.build(  # type: ignore[union-attr]
         ^^^^^^^^^^^^^^^^^^^^^^^^^^^^^^^^^^^^^^^^^^^^^^
  File "C:\Users\as222\flask_project1\venv\Lib\site-packages\werkzeug\routing\map.py", line 917, in build
    raise BuildError(endpoint, values, method, self)
werkzeug.routing.exceptions.BuildError: Could not build url for endpoint 'view_photo' with values ['photo_id']. Did you mean 'show_post' instead?
2023-03-20 22:04:49,577 - apps - ERROR - Exception on /photo/2 [GET]
Traceback (most recent call last):
  File "C:\Users\as222\flask_project1\venv\Lib\site-packages\flask\app.py", line 2528, in wsgi_app
    response = self.full_dispatch_request()
               ^^^^^^^^^^^^^^^^^^^^^^^^^^^^
  File "C:\Users\as222\flask_project1\venv\Lib\site-packages\flask\app.py", line 1825, in full_dispatch_request
    rv = self.handle_user_exception(e)
         ^^^^^^^^^^^^^^^^^^^^^^^^^^^^^
  File "C:\Users\as222\flask_project1\venv\Lib\site-packages\flask\app.py", line 1823, in full_dispatch_request
    rv = self.dispatch_request()
         ^^^^^^^^^^^^^^^^^^^^^^^
  File "C:\Users\as222\flask_project1\venv\Lib\site-packages\flask\app.py", line 1799, in dispatch_request
    return self.ensure_sync(self.view_functions[rule.endpoint])(**view_args)
           ^^^^^^^^^^^^^^^^^^^^^^^^^^^^^^^^^^^^^^^^^^^^^^^^^^^^^^^^^^^^^^^^^
  File "C:\Users\as222\flask_project2\router.py", line 158, in view_photo
    photo_url = url_for('static/image/upload', filename=photo.filename)
                                                        ^^^^^^^^^^^^^^
AttributeError: 'Photos' object has no attribute 'filename'
2023-03-20 22:05:39,323 - apps - ERROR - Exception on /photo/3 [GET]
Traceback (most recent call last):
  File "C:\Users\as222\flask_project1\venv\Lib\site-packages\flask\app.py", line 2528, in wsgi_app
    response = self.full_dispatch_request()
               ^^^^^^^^^^^^^^^^^^^^^^^^^^^^
  File "C:\Users\as222\flask_project1\venv\Lib\site-packages\flask\app.py", line 1825, in full_dispatch_request
    rv = self.handle_user_exception(e)
         ^^^^^^^^^^^^^^^^^^^^^^^^^^^^^
  File "C:\Users\as222\flask_project1\venv\Lib\site-packages\flask\app.py", line 1823, in full_dispatch_request
    rv = self.dispatch_request()
         ^^^^^^^^^^^^^^^^^^^^^^^
  File "C:\Users\as222\flask_project1\venv\Lib\site-packages\flask\app.py", line 1799, in dispatch_request
    return self.ensure_sync(self.view_functions[rule.endpoint])(**view_args)
           ^^^^^^^^^^^^^^^^^^^^^^^^^^^^^^^^^^^^^^^^^^^^^^^^^^^^^^^^^^^^^^^^^
  File "C:\Users\as222\flask_project2\router.py", line 158, in view_photo
    photo_url = url_for('static/image/upload', filename=photo.Filename)
                ^^^^^^^^^^^^^^^^^^^^^^^^^^^^^^^^^^^^^^^^^^^^^^^^^^^^^^^
  File "C:\Users\as222\flask_project1\venv\Lib\site-packages\flask\helpers.py", line 256, in url_for
    return current_app.url_for(
           ^^^^^^^^^^^^^^^^^^^^
  File "C:\Users\as222\flask_project1\venv\Lib\site-packages\flask\app.py", line 2034, in url_for
    return self.handle_url_build_error(error, endpoint, values)
           ^^^^^^^^^^^^^^^^^^^^^^^^^^^^^^^^^^^^^^^^^^^^^^^^^^^^
  File "C:\Users\as222\flask_project1\venv\Lib\site-packages\flask\app.py", line 2023, in url_for
    rv = url_adapter.build(  # type: ignore[union-attr]
         ^^^^^^^^^^^^^^^^^^^^^^^^^^^^^^^^^^^^^^^^^^^^^^
  File "C:\Users\as222\flask_project1\venv\Lib\site-packages\werkzeug\routing\map.py", line 917, in build
    raise BuildError(endpoint, values, method, self)
werkzeug.routing.exceptions.BuildError: Could not build url for endpoint 'static/image/upload' with values ['filename']. Did you mean 'static' instead?
2023-03-20 22:09:46,643 - apps - ERROR - Exception on /photo/4 [GET]
Traceback (most recent call last):
  File "C:\Users\as222\flask_project1\venv\Lib\site-packages\flask\app.py", line 2528, in wsgi_app
    response = self.full_dispatch_request()
               ^^^^^^^^^^^^^^^^^^^^^^^^^^^^
  File "C:\Users\as222\flask_project1\venv\Lib\site-packages\flask\app.py", line 1825, in full_dispatch_request
    rv = self.handle_user_exception(e)
         ^^^^^^^^^^^^^^^^^^^^^^^^^^^^^
  File "C:\Users\as222\flask_project1\venv\Lib\site-packages\flask\app.py", line 1823, in full_dispatch_request
    rv = self.dispatch_request()
         ^^^^^^^^^^^^^^^^^^^^^^^
  File "C:\Users\as222\flask_project1\venv\Lib\site-packages\flask\app.py", line 1799, in dispatch_request
    return self.ensure_sync(self.view_functions[rule.endpoint])(**view_args)
           ^^^^^^^^^^^^^^^^^^^^^^^^^^^^^^^^^^^^^^^^^^^^^^^^^^^^^^^^^^^^^^^^^
  File "C:\Users\as222\flask_project2\router.py", line 159, in view_photo
    return render_template('user/show_photo.html',photo=photo)
           ^^^^^^^^^^^^^^^^^^^^^^^^^^^^^^^^^^^^^^^^^^^^^^^^^^^
  File "C:\Users\as222\flask_project1\venv\Lib\site-packages\flask\templating.py", line 147, in render_template
    return _render(app, template, context)
           ^^^^^^^^^^^^^^^^^^^^^^^^^^^^^^^
  File "C:\Users\as222\flask_project1\venv\Lib\site-packages\flask\templating.py", line 130, in _render
    rv = template.render(context)
         ^^^^^^^^^^^^^^^^^^^^^^^^
  File "C:\Users\as222\flask_project1\venv\Lib\site-packages\jinja2\environment.py", line 1301, in render
    self.environment.handle_exception()
  File "C:\Users\as222\flask_project1\venv\Lib\site-packages\jinja2\environment.py", line 936, in handle_exception
    raise rewrite_traceback_stack(source=source)
  File "C:\Users\as222\flask_project2\apps\templates\user\show_photo.html", line 1, in top-level template code
    {% extends "user/layout.html" %}
    ^^^^^^^^^^^^^^^^^^^^^^^^^
  File "C:\Users\as222\flask_project2\apps\templates\user\layout.html", line 13, in top-level template code
    {% block body %} {% endblock %}
    ^^^^^^^^^^^^^^^^^^^^^^^^^
  File "C:\Users\as222\flask_project2\apps\templates\user\show_photo.html", line 61, in block 'body'
    <img src="{{ url_for('static/image/upload', filename=photo.Filename) }}" alt="{{ photo.Name }}" width="500px">
    ^^^^^^^^^^^^^^^^^^^^^^^^^
  File "C:\Users\as222\flask_project1\venv\Lib\site-packages\flask\app.py", line 2034, in url_for
    return self.handle_url_build_error(error, endpoint, values)
           ^^^^^^^^^^^^^^^^^^^^^^^^^^^^^^^^^^^^^^^^^^^^^^^^^^^^
  File "C:\Users\as222\flask_project1\venv\Lib\site-packages\flask\app.py", line 2023, in url_for
    rv = url_adapter.build(  # type: ignore[union-attr]
         ^^^^^^^^^^^^^^^^^^^^^^^^^^^^^^^^^^^^^^^^^^^^^^
  File "C:\Users\as222\flask_project1\venv\Lib\site-packages\werkzeug\routing\map.py", line 917, in build
    raise BuildError(endpoint, values, method, self)
werkzeug.routing.exceptions.BuildError: Could not build url for endpoint 'static/image/upload' with values ['filename']. Did you mean 'static' instead?
2023-03-21 08:36:53,493 - apps - ERROR - Exception on /photo/4 [GET]
Traceback (most recent call last):
  File "C:\Users\as222\flask_project1\venv\Lib\site-packages\sqlalchemy\engine\base.py", line 1964, in _exec_single_context
    self.dialect.do_execute(
  File "C:\Users\as222\flask_project1\venv\Lib\site-packages\sqlalchemy\engine\default.py", line 747, in do_execute
    cursor.execute(statement, parameters)
  File "C:\Users\as222\flask_project1\venv\Lib\site-packages\pymysql\cursors.py", line 148, in execute
    result = self._query(query)
             ^^^^^^^^^^^^^^^^^^
  File "C:\Users\as222\flask_project1\venv\Lib\site-packages\pymysql\cursors.py", line 310, in _query
    conn.query(q)
  File "C:\Users\as222\flask_project1\venv\Lib\site-packages\pymysql\connections.py", line 548, in query
    self._affected_rows = self._read_query_result(unbuffered=unbuffered)
                          ^^^^^^^^^^^^^^^^^^^^^^^^^^^^^^^^^^^^^^^^^^^^^^
  File "C:\Users\as222\flask_project1\venv\Lib\site-packages\pymysql\connections.py", line 775, in _read_query_result
    result.read()
  File "C:\Users\as222\flask_project1\venv\Lib\site-packages\pymysql\connections.py", line 1156, in read
    first_packet = self.connection._read_packet()
                   ^^^^^^^^^^^^^^^^^^^^^^^^^^^^^^
  File "C:\Users\as222\flask_project1\venv\Lib\site-packages\pymysql\connections.py", line 725, in _read_packet
    packet.raise_for_error()
  File "C:\Users\as222\flask_project1\venv\Lib\site-packages\pymysql\protocol.py", line 221, in raise_for_error
    err.raise_mysql_exception(self._data)
  File "C:\Users\as222\flask_project1\venv\Lib\site-packages\pymysql\err.py", line 143, in raise_mysql_exception
    raise errorclass(errno, errval)
pymysql.err.OperationalError: (1054, "Unknown column 'photos.Special_Filename' in 'field list'")

The above exception was the direct cause of the following exception:

Traceback (most recent call last):
  File "C:\Users\as222\flask_project1\venv\Lib\site-packages\flask\app.py", line 2528, in wsgi_app
    response = self.full_dispatch_request()
               ^^^^^^^^^^^^^^^^^^^^^^^^^^^^
  File "C:\Users\as222\flask_project1\venv\Lib\site-packages\flask\app.py", line 1825, in full_dispatch_request
    rv = self.handle_user_exception(e)
         ^^^^^^^^^^^^^^^^^^^^^^^^^^^^^
  File "C:\Users\as222\flask_project1\venv\Lib\site-packages\flask\app.py", line 1823, in full_dispatch_request
    rv = self.dispatch_request()
         ^^^^^^^^^^^^^^^^^^^^^^^
  File "C:\Users\as222\flask_project1\venv\Lib\site-packages\flask\app.py", line 1799, in dispatch_request
    return self.ensure_sync(self.view_functions[rule.endpoint])(**view_args)
           ^^^^^^^^^^^^^^^^^^^^^^^^^^^^^^^^^^^^^^^^^^^^^^^^^^^^^^^^^^^^^^^^^
  File "C:\Users\as222\flask_project2\router.py", line 154, in view_photo
    photo=Photos.query.filter_by(id=photo_id).first()
          ^^^^^^^^^^^^^^^^^^^^^^^^^^^^^^^^^^^^^^^^^^^
  File "C:\Users\as222\flask_project1\venv\Lib\site-packages\sqlalchemy\orm\query.py", line 2752, in first
    return self.limit(1)._iter().first()  # type: ignore
           ^^^^^^^^^^^^^^^^^^^^^
  File "C:\Users\as222\flask_project1\venv\Lib\site-packages\sqlalchemy\orm\query.py", line 2855, in _iter
    result: Union[ScalarResult[_T], Result[_T]] = self.session.execute(
                                                  ^^^^^^^^^^^^^^^^^^^^^
  File "C:\Users\as222\flask_project1\venv\Lib\site-packages\sqlalchemy\orm\session.py", line 2229, in execute
    return self._execute_internal(
           ^^^^^^^^^^^^^^^^^^^^^^^
  File "C:\Users\as222\flask_project1\venv\Lib\site-packages\sqlalchemy\orm\session.py", line 2124, in _execute_internal
    result: Result[Any] = compile_state_cls.orm_execute_statement(
                          ^^^^^^^^^^^^^^^^^^^^^^^^^^^^^^^^^^^^^^^^
  File "C:\Users\as222\flask_project1\venv\Lib\site-packages\sqlalchemy\orm\context.py", line 253, in orm_execute_statement
    result = conn.execute(
             ^^^^^^^^^^^^^
  File "C:\Users\as222\flask_project1\venv\Lib\site-packages\sqlalchemy\engine\base.py", line 1414, in execute
    return meth(
           ^^^^^
  File "C:\Users\as222\flask_project1\venv\Lib\site-packages\sqlalchemy\sql\elements.py", line 485, in _execute_on_connection
    return connection._execute_clauseelement(
           ^^^^^^^^^^^^^^^^^^^^^^^^^^^^^^^^^^
  File "C:\Users\as222\flask_project1\venv\Lib\site-packages\sqlalchemy\engine\base.py", line 1638, in _execute_clauseelement
    ret = self._execute_context(
          ^^^^^^^^^^^^^^^^^^^^^^
  File "C:\Users\as222\flask_project1\venv\Lib\site-packages\sqlalchemy\engine\base.py", line 1842, in _execute_context
    return self._exec_single_context(
           ^^^^^^^^^^^^^^^^^^^^^^^^^^
  File "C:\Users\as222\flask_project1\venv\Lib\site-packages\sqlalchemy\engine\base.py", line 1983, in _exec_single_context
    self._handle_dbapi_exception(
  File "C:\Users\as222\flask_project1\venv\Lib\site-packages\sqlalchemy\engine\base.py", line 2325, in _handle_dbapi_exception
    raise sqlalchemy_exception.with_traceback(exc_info[2]) from e
  File "C:\Users\as222\flask_project1\venv\Lib\site-packages\sqlalchemy\engine\base.py", line 1964, in _exec_single_context
    self.dialect.do_execute(
  File "C:\Users\as222\flask_project1\venv\Lib\site-packages\sqlalchemy\engine\default.py", line 747, in do_execute
    cursor.execute(statement, parameters)
  File "C:\Users\as222\flask_project1\venv\Lib\site-packages\pymysql\cursors.py", line 148, in execute
    result = self._query(query)
             ^^^^^^^^^^^^^^^^^^
  File "C:\Users\as222\flask_project1\venv\Lib\site-packages\pymysql\cursors.py", line 310, in _query
    conn.query(q)
  File "C:\Users\as222\flask_project1\venv\Lib\site-packages\pymysql\connections.py", line 548, in query
    self._affected_rows = self._read_query_result(unbuffered=unbuffered)
                          ^^^^^^^^^^^^^^^^^^^^^^^^^^^^^^^^^^^^^^^^^^^^^^
  File "C:\Users\as222\flask_project1\venv\Lib\site-packages\pymysql\connections.py", line 775, in _read_query_result
    result.read()
  File "C:\Users\as222\flask_project1\venv\Lib\site-packages\pymysql\connections.py", line 1156, in read
    first_packet = self.connection._read_packet()
                   ^^^^^^^^^^^^^^^^^^^^^^^^^^^^^^
  File "C:\Users\as222\flask_project1\venv\Lib\site-packages\pymysql\connections.py", line 725, in _read_packet
    packet.raise_for_error()
  File "C:\Users\as222\flask_project1\venv\Lib\site-packages\pymysql\protocol.py", line 221, in raise_for_error
    err.raise_mysql_exception(self._data)
  File "C:\Users\as222\flask_project1\venv\Lib\site-packages\pymysql\err.py", line 143, in raise_mysql_exception
    raise errorclass(errno, errval)
sqlalchemy.exc.OperationalError: (pymysql.err.OperationalError) (1054, "Unknown column 'photos.Special_Filename' in 'field list'")
[SQL: SELECT photos.id AS photos_id, photos.`Name` AS `photos_Name`, photos.`Filename` AS `photos_Filename`, photos.`Special_Filename` AS `photos_Special_Filename`, photos.`Description` AS `photos_Description`, photos.`Upload_time` AS `photos_Upload_time` 
FROM photos 
WHERE photos.id = %(id_1)s 
 LIMIT %(param_1)s]
[parameters: {'id_1': 4, 'param_1': 1}]
(Background on this error at: https://sqlalche.me/e/20/e3q8)
2023-03-21 08:36:55,531 - apps - ERROR - Exception on /photo/4 [GET]
Traceback (most recent call last):
  File "C:\Users\as222\flask_project1\venv\Lib\site-packages\sqlalchemy\engine\base.py", line 1964, in _exec_single_context
    self.dialect.do_execute(
  File "C:\Users\as222\flask_project1\venv\Lib\site-packages\sqlalchemy\engine\default.py", line 747, in do_execute
    cursor.execute(statement, parameters)
  File "C:\Users\as222\flask_project1\venv\Lib\site-packages\pymysql\cursors.py", line 148, in execute
    result = self._query(query)
             ^^^^^^^^^^^^^^^^^^
  File "C:\Users\as222\flask_project1\venv\Lib\site-packages\pymysql\cursors.py", line 310, in _query
    conn.query(q)
  File "C:\Users\as222\flask_project1\venv\Lib\site-packages\pymysql\connections.py", line 548, in query
    self._affected_rows = self._read_query_result(unbuffered=unbuffered)
                          ^^^^^^^^^^^^^^^^^^^^^^^^^^^^^^^^^^^^^^^^^^^^^^
  File "C:\Users\as222\flask_project1\venv\Lib\site-packages\pymysql\connections.py", line 775, in _read_query_result
    result.read()
  File "C:\Users\as222\flask_project1\venv\Lib\site-packages\pymysql\connections.py", line 1156, in read
    first_packet = self.connection._read_packet()
                   ^^^^^^^^^^^^^^^^^^^^^^^^^^^^^^
  File "C:\Users\as222\flask_project1\venv\Lib\site-packages\pymysql\connections.py", line 725, in _read_packet
    packet.raise_for_error()
  File "C:\Users\as222\flask_project1\venv\Lib\site-packages\pymysql\protocol.py", line 221, in raise_for_error
    err.raise_mysql_exception(self._data)
  File "C:\Users\as222\flask_project1\venv\Lib\site-packages\pymysql\err.py", line 143, in raise_mysql_exception
    raise errorclass(errno, errval)
pymysql.err.OperationalError: (1054, "Unknown column 'photos.Special_Filename' in 'field list'")

The above exception was the direct cause of the following exception:

Traceback (most recent call last):
  File "C:\Users\as222\flask_project1\venv\Lib\site-packages\flask\app.py", line 2528, in wsgi_app
    response = self.full_dispatch_request()
               ^^^^^^^^^^^^^^^^^^^^^^^^^^^^
  File "C:\Users\as222\flask_project1\venv\Lib\site-packages\flask\app.py", line 1825, in full_dispatch_request
    rv = self.handle_user_exception(e)
         ^^^^^^^^^^^^^^^^^^^^^^^^^^^^^
  File "C:\Users\as222\flask_project1\venv\Lib\site-packages\flask\app.py", line 1823, in full_dispatch_request
    rv = self.dispatch_request()
         ^^^^^^^^^^^^^^^^^^^^^^^
  File "C:\Users\as222\flask_project1\venv\Lib\site-packages\flask\app.py", line 1799, in dispatch_request
    return self.ensure_sync(self.view_functions[rule.endpoint])(**view_args)
           ^^^^^^^^^^^^^^^^^^^^^^^^^^^^^^^^^^^^^^^^^^^^^^^^^^^^^^^^^^^^^^^^^
  File "C:\Users\as222\flask_project2\router.py", line 154, in view_photo
    photo=Photos.query.filter_by(id=photo_id).first()
          ^^^^^^^^^^^^^^^^^^^^^^^^^^^^^^^^^^^^^^^^^^^
  File "C:\Users\as222\flask_project1\venv\Lib\site-packages\sqlalchemy\orm\query.py", line 2752, in first
    return self.limit(1)._iter().first()  # type: ignore
           ^^^^^^^^^^^^^^^^^^^^^
  File "C:\Users\as222\flask_project1\venv\Lib\site-packages\sqlalchemy\orm\query.py", line 2855, in _iter
    result: Union[ScalarResult[_T], Result[_T]] = self.session.execute(
                                                  ^^^^^^^^^^^^^^^^^^^^^
  File "C:\Users\as222\flask_project1\venv\Lib\site-packages\sqlalchemy\orm\session.py", line 2229, in execute
    return self._execute_internal(
           ^^^^^^^^^^^^^^^^^^^^^^^
  File "C:\Users\as222\flask_project1\venv\Lib\site-packages\sqlalchemy\orm\session.py", line 2124, in _execute_internal
    result: Result[Any] = compile_state_cls.orm_execute_statement(
                          ^^^^^^^^^^^^^^^^^^^^^^^^^^^^^^^^^^^^^^^^
  File "C:\Users\as222\flask_project1\venv\Lib\site-packages\sqlalchemy\orm\context.py", line 253, in orm_execute_statement
    result = conn.execute(
             ^^^^^^^^^^^^^
  File "C:\Users\as222\flask_project1\venv\Lib\site-packages\sqlalchemy\engine\base.py", line 1414, in execute
    return meth(
           ^^^^^
  File "C:\Users\as222\flask_project1\venv\Lib\site-packages\sqlalchemy\sql\elements.py", line 485, in _execute_on_connection
    return connection._execute_clauseelement(
           ^^^^^^^^^^^^^^^^^^^^^^^^^^^^^^^^^^
  File "C:\Users\as222\flask_project1\venv\Lib\site-packages\sqlalchemy\engine\base.py", line 1638, in _execute_clauseelement
    ret = self._execute_context(
          ^^^^^^^^^^^^^^^^^^^^^^
  File "C:\Users\as222\flask_project1\venv\Lib\site-packages\sqlalchemy\engine\base.py", line 1842, in _execute_context
    return self._exec_single_context(
           ^^^^^^^^^^^^^^^^^^^^^^^^^^
  File "C:\Users\as222\flask_project1\venv\Lib\site-packages\sqlalchemy\engine\base.py", line 1983, in _exec_single_context
    self._handle_dbapi_exception(
  File "C:\Users\as222\flask_project1\venv\Lib\site-packages\sqlalchemy\engine\base.py", line 2325, in _handle_dbapi_exception
    raise sqlalchemy_exception.with_traceback(exc_info[2]) from e
  File "C:\Users\as222\flask_project1\venv\Lib\site-packages\sqlalchemy\engine\base.py", line 1964, in _exec_single_context
    self.dialect.do_execute(
  File "C:\Users\as222\flask_project1\venv\Lib\site-packages\sqlalchemy\engine\default.py", line 747, in do_execute
    cursor.execute(statement, parameters)
  File "C:\Users\as222\flask_project1\venv\Lib\site-packages\pymysql\cursors.py", line 148, in execute
    result = self._query(query)
             ^^^^^^^^^^^^^^^^^^
  File "C:\Users\as222\flask_project1\venv\Lib\site-packages\pymysql\cursors.py", line 310, in _query
    conn.query(q)
  File "C:\Users\as222\flask_project1\venv\Lib\site-packages\pymysql\connections.py", line 548, in query
    self._affected_rows = self._read_query_result(unbuffered=unbuffered)
                          ^^^^^^^^^^^^^^^^^^^^^^^^^^^^^^^^^^^^^^^^^^^^^^
  File "C:\Users\as222\flask_project1\venv\Lib\site-packages\pymysql\connections.py", line 775, in _read_query_result
    result.read()
  File "C:\Users\as222\flask_project1\venv\Lib\site-packages\pymysql\connections.py", line 1156, in read
    first_packet = self.connection._read_packet()
                   ^^^^^^^^^^^^^^^^^^^^^^^^^^^^^^
  File "C:\Users\as222\flask_project1\venv\Lib\site-packages\pymysql\connections.py", line 725, in _read_packet
    packet.raise_for_error()
  File "C:\Users\as222\flask_project1\venv\Lib\site-packages\pymysql\protocol.py", line 221, in raise_for_error
    err.raise_mysql_exception(self._data)
  File "C:\Users\as222\flask_project1\venv\Lib\site-packages\pymysql\err.py", line 143, in raise_mysql_exception
    raise errorclass(errno, errval)
sqlalchemy.exc.OperationalError: (pymysql.err.OperationalError) (1054, "Unknown column 'photos.Special_Filename' in 'field list'")
[SQL: SELECT photos.id AS photos_id, photos.`Name` AS `photos_Name`, photos.`Filename` AS `photos_Filename`, photos.`Special_Filename` AS `photos_Special_Filename`, photos.`Description` AS `photos_Description`, photos.`Upload_time` AS `photos_Upload_time` 
FROM photos 
WHERE photos.id = %(id_1)s 
 LIMIT %(param_1)s]
[parameters: {'id_1': 4, 'param_1': 1}]
(Background on this error at: https://sqlalche.me/e/20/e3q8)
2023-03-21 08:37:03,604 - apps - ERROR - Exception on /photo/1 [GET]
Traceback (most recent call last):
  File "C:\Users\as222\flask_project1\venv\Lib\site-packages\sqlalchemy\engine\base.py", line 1964, in _exec_single_context
    self.dialect.do_execute(
  File "C:\Users\as222\flask_project1\venv\Lib\site-packages\sqlalchemy\engine\default.py", line 747, in do_execute
    cursor.execute(statement, parameters)
  File "C:\Users\as222\flask_project1\venv\Lib\site-packages\pymysql\cursors.py", line 148, in execute
    result = self._query(query)
             ^^^^^^^^^^^^^^^^^^
  File "C:\Users\as222\flask_project1\venv\Lib\site-packages\pymysql\cursors.py", line 310, in _query
    conn.query(q)
  File "C:\Users\as222\flask_project1\venv\Lib\site-packages\pymysql\connections.py", line 548, in query
    self._affected_rows = self._read_query_result(unbuffered=unbuffered)
                          ^^^^^^^^^^^^^^^^^^^^^^^^^^^^^^^^^^^^^^^^^^^^^^
  File "C:\Users\as222\flask_project1\venv\Lib\site-packages\pymysql\connections.py", line 775, in _read_query_result
    result.read()
  File "C:\Users\as222\flask_project1\venv\Lib\site-packages\pymysql\connections.py", line 1156, in read
    first_packet = self.connection._read_packet()
                   ^^^^^^^^^^^^^^^^^^^^^^^^^^^^^^
  File "C:\Users\as222\flask_project1\venv\Lib\site-packages\pymysql\connections.py", line 725, in _read_packet
    packet.raise_for_error()
  File "C:\Users\as222\flask_project1\venv\Lib\site-packages\pymysql\protocol.py", line 221, in raise_for_error
    err.raise_mysql_exception(self._data)
  File "C:\Users\as222\flask_project1\venv\Lib\site-packages\pymysql\err.py", line 143, in raise_mysql_exception
    raise errorclass(errno, errval)
pymysql.err.OperationalError: (1054, "Unknown column 'photos.Special_Filename' in 'field list'")

The above exception was the direct cause of the following exception:

Traceback (most recent call last):
  File "C:\Users\as222\flask_project1\venv\Lib\site-packages\flask\app.py", line 2528, in wsgi_app
    response = self.full_dispatch_request()
               ^^^^^^^^^^^^^^^^^^^^^^^^^^^^
  File "C:\Users\as222\flask_project1\venv\Lib\site-packages\flask\app.py", line 1825, in full_dispatch_request
    rv = self.handle_user_exception(e)
         ^^^^^^^^^^^^^^^^^^^^^^^^^^^^^
  File "C:\Users\as222\flask_project1\venv\Lib\site-packages\flask\app.py", line 1823, in full_dispatch_request
    rv = self.dispatch_request()
         ^^^^^^^^^^^^^^^^^^^^^^^
  File "C:\Users\as222\flask_project1\venv\Lib\site-packages\flask\app.py", line 1799, in dispatch_request
    return self.ensure_sync(self.view_functions[rule.endpoint])(**view_args)
           ^^^^^^^^^^^^^^^^^^^^^^^^^^^^^^^^^^^^^^^^^^^^^^^^^^^^^^^^^^^^^^^^^
  File "C:\Users\as222\flask_project2\router.py", line 154, in view_photo
    photo=Photos.query.filter_by(id=photo_id).first()
          ^^^^^^^^^^^^^^^^^^^^^^^^^^^^^^^^^^^^^^^^^^^
  File "C:\Users\as222\flask_project1\venv\Lib\site-packages\sqlalchemy\orm\query.py", line 2752, in first
    return self.limit(1)._iter().first()  # type: ignore
           ^^^^^^^^^^^^^^^^^^^^^
  File "C:\Users\as222\flask_project1\venv\Lib\site-packages\sqlalchemy\orm\query.py", line 2855, in _iter
    result: Union[ScalarResult[_T], Result[_T]] = self.session.execute(
                                                  ^^^^^^^^^^^^^^^^^^^^^
  File "C:\Users\as222\flask_project1\venv\Lib\site-packages\sqlalchemy\orm\session.py", line 2229, in execute
    return self._execute_internal(
           ^^^^^^^^^^^^^^^^^^^^^^^
  File "C:\Users\as222\flask_project1\venv\Lib\site-packages\sqlalchemy\orm\session.py", line 2124, in _execute_internal
    result: Result[Any] = compile_state_cls.orm_execute_statement(
                          ^^^^^^^^^^^^^^^^^^^^^^^^^^^^^^^^^^^^^^^^
  File "C:\Users\as222\flask_project1\venv\Lib\site-packages\sqlalchemy\orm\context.py", line 253, in orm_execute_statement
    result = conn.execute(
             ^^^^^^^^^^^^^
  File "C:\Users\as222\flask_project1\venv\Lib\site-packages\sqlalchemy\engine\base.py", line 1414, in execute
    return meth(
           ^^^^^
  File "C:\Users\as222\flask_project1\venv\Lib\site-packages\sqlalchemy\sql\elements.py", line 485, in _execute_on_connection
    return connection._execute_clauseelement(
           ^^^^^^^^^^^^^^^^^^^^^^^^^^^^^^^^^^
  File "C:\Users\as222\flask_project1\venv\Lib\site-packages\sqlalchemy\engine\base.py", line 1638, in _execute_clauseelement
    ret = self._execute_context(
          ^^^^^^^^^^^^^^^^^^^^^^
  File "C:\Users\as222\flask_project1\venv\Lib\site-packages\sqlalchemy\engine\base.py", line 1842, in _execute_context
    return self._exec_single_context(
           ^^^^^^^^^^^^^^^^^^^^^^^^^^
  File "C:\Users\as222\flask_project1\venv\Lib\site-packages\sqlalchemy\engine\base.py", line 1983, in _exec_single_context
    self._handle_dbapi_exception(
  File "C:\Users\as222\flask_project1\venv\Lib\site-packages\sqlalchemy\engine\base.py", line 2325, in _handle_dbapi_exception
    raise sqlalchemy_exception.with_traceback(exc_info[2]) from e
  File "C:\Users\as222\flask_project1\venv\Lib\site-packages\sqlalchemy\engine\base.py", line 1964, in _exec_single_context
    self.dialect.do_execute(
  File "C:\Users\as222\flask_project1\venv\Lib\site-packages\sqlalchemy\engine\default.py", line 747, in do_execute
    cursor.execute(statement, parameters)
  File "C:\Users\as222\flask_project1\venv\Lib\site-packages\pymysql\cursors.py", line 148, in execute
    result = self._query(query)
             ^^^^^^^^^^^^^^^^^^
  File "C:\Users\as222\flask_project1\venv\Lib\site-packages\pymysql\cursors.py", line 310, in _query
    conn.query(q)
  File "C:\Users\as222\flask_project1\venv\Lib\site-packages\pymysql\connections.py", line 548, in query
    self._affected_rows = self._read_query_result(unbuffered=unbuffered)
                          ^^^^^^^^^^^^^^^^^^^^^^^^^^^^^^^^^^^^^^^^^^^^^^
  File "C:\Users\as222\flask_project1\venv\Lib\site-packages\pymysql\connections.py", line 775, in _read_query_result
    result.read()
  File "C:\Users\as222\flask_project1\venv\Lib\site-packages\pymysql\connections.py", line 1156, in read
    first_packet = self.connection._read_packet()
                   ^^^^^^^^^^^^^^^^^^^^^^^^^^^^^^
  File "C:\Users\as222\flask_project1\venv\Lib\site-packages\pymysql\connections.py", line 725, in _read_packet
    packet.raise_for_error()
  File "C:\Users\as222\flask_project1\venv\Lib\site-packages\pymysql\protocol.py", line 221, in raise_for_error
    err.raise_mysql_exception(self._data)
  File "C:\Users\as222\flask_project1\venv\Lib\site-packages\pymysql\err.py", line 143, in raise_mysql_exception
    raise errorclass(errno, errval)
sqlalchemy.exc.OperationalError: (pymysql.err.OperationalError) (1054, "Unknown column 'photos.Special_Filename' in 'field list'")
[SQL: SELECT photos.id AS photos_id, photos.`Name` AS `photos_Name`, photos.`Filename` AS `photos_Filename`, photos.`Special_Filename` AS `photos_Special_Filename`, photos.`Description` AS `photos_Description`, photos.`Upload_time` AS `photos_Upload_time` 
FROM photos 
WHERE photos.id = %(id_1)s 
 LIMIT %(param_1)s]
[parameters: {'id_1': 1, 'param_1': 1}]
(Background on this error at: https://sqlalche.me/e/20/e3q8)
2023-03-21 08:37:05,577 - apps - ERROR - Exception on /photo/1 [GET]
Traceback (most recent call last):
  File "C:\Users\as222\flask_project1\venv\Lib\site-packages\sqlalchemy\engine\base.py", line 1964, in _exec_single_context
    self.dialect.do_execute(
  File "C:\Users\as222\flask_project1\venv\Lib\site-packages\sqlalchemy\engine\default.py", line 747, in do_execute
    cursor.execute(statement, parameters)
  File "C:\Users\as222\flask_project1\venv\Lib\site-packages\pymysql\cursors.py", line 148, in execute
    result = self._query(query)
             ^^^^^^^^^^^^^^^^^^
  File "C:\Users\as222\flask_project1\venv\Lib\site-packages\pymysql\cursors.py", line 310, in _query
    conn.query(q)
  File "C:\Users\as222\flask_project1\venv\Lib\site-packages\pymysql\connections.py", line 548, in query
    self._affected_rows = self._read_query_result(unbuffered=unbuffered)
                          ^^^^^^^^^^^^^^^^^^^^^^^^^^^^^^^^^^^^^^^^^^^^^^
  File "C:\Users\as222\flask_project1\venv\Lib\site-packages\pymysql\connections.py", line 775, in _read_query_result
    result.read()
  File "C:\Users\as222\flask_project1\venv\Lib\site-packages\pymysql\connections.py", line 1156, in read
    first_packet = self.connection._read_packet()
                   ^^^^^^^^^^^^^^^^^^^^^^^^^^^^^^
  File "C:\Users\as222\flask_project1\venv\Lib\site-packages\pymysql\connections.py", line 725, in _read_packet
    packet.raise_for_error()
  File "C:\Users\as222\flask_project1\venv\Lib\site-packages\pymysql\protocol.py", line 221, in raise_for_error
    err.raise_mysql_exception(self._data)
  File "C:\Users\as222\flask_project1\venv\Lib\site-packages\pymysql\err.py", line 143, in raise_mysql_exception
    raise errorclass(errno, errval)
pymysql.err.OperationalError: (1054, "Unknown column 'photos.Special_Filename' in 'field list'")

The above exception was the direct cause of the following exception:

Traceback (most recent call last):
  File "C:\Users\as222\flask_project1\venv\Lib\site-packages\flask\app.py", line 2528, in wsgi_app
    response = self.full_dispatch_request()
               ^^^^^^^^^^^^^^^^^^^^^^^^^^^^
  File "C:\Users\as222\flask_project1\venv\Lib\site-packages\flask\app.py", line 1825, in full_dispatch_request
    rv = self.handle_user_exception(e)
         ^^^^^^^^^^^^^^^^^^^^^^^^^^^^^
  File "C:\Users\as222\flask_project1\venv\Lib\site-packages\flask\app.py", line 1823, in full_dispatch_request
    rv = self.dispatch_request()
         ^^^^^^^^^^^^^^^^^^^^^^^
  File "C:\Users\as222\flask_project1\venv\Lib\site-packages\flask\app.py", line 1799, in dispatch_request
    return self.ensure_sync(self.view_functions[rule.endpoint])(**view_args)
           ^^^^^^^^^^^^^^^^^^^^^^^^^^^^^^^^^^^^^^^^^^^^^^^^^^^^^^^^^^^^^^^^^
  File "C:\Users\as222\flask_project2\router.py", line 154, in view_photo
    photo=Photos.query.filter_by(id=photo_id).first()
          ^^^^^^^^^^^^^^^^^^^^^^^^^^^^^^^^^^^^^^^^^^^
  File "C:\Users\as222\flask_project1\venv\Lib\site-packages\sqlalchemy\orm\query.py", line 2752, in first
    return self.limit(1)._iter().first()  # type: ignore
           ^^^^^^^^^^^^^^^^^^^^^
  File "C:\Users\as222\flask_project1\venv\Lib\site-packages\sqlalchemy\orm\query.py", line 2855, in _iter
    result: Union[ScalarResult[_T], Result[_T]] = self.session.execute(
                                                  ^^^^^^^^^^^^^^^^^^^^^
  File "C:\Users\as222\flask_project1\venv\Lib\site-packages\sqlalchemy\orm\session.py", line 2229, in execute
    return self._execute_internal(
           ^^^^^^^^^^^^^^^^^^^^^^^
  File "C:\Users\as222\flask_project1\venv\Lib\site-packages\sqlalchemy\orm\session.py", line 2124, in _execute_internal
    result: Result[Any] = compile_state_cls.orm_execute_statement(
                          ^^^^^^^^^^^^^^^^^^^^^^^^^^^^^^^^^^^^^^^^
  File "C:\Users\as222\flask_project1\venv\Lib\site-packages\sqlalchemy\orm\context.py", line 253, in orm_execute_statement
    result = conn.execute(
             ^^^^^^^^^^^^^
  File "C:\Users\as222\flask_project1\venv\Lib\site-packages\sqlalchemy\engine\base.py", line 1414, in execute
    return meth(
           ^^^^^
  File "C:\Users\as222\flask_project1\venv\Lib\site-packages\sqlalchemy\sql\elements.py", line 485, in _execute_on_connection
    return connection._execute_clauseelement(
           ^^^^^^^^^^^^^^^^^^^^^^^^^^^^^^^^^^
  File "C:\Users\as222\flask_project1\venv\Lib\site-packages\sqlalchemy\engine\base.py", line 1638, in _execute_clauseelement
    ret = self._execute_context(
          ^^^^^^^^^^^^^^^^^^^^^^
  File "C:\Users\as222\flask_project1\venv\Lib\site-packages\sqlalchemy\engine\base.py", line 1842, in _execute_context
    return self._exec_single_context(
           ^^^^^^^^^^^^^^^^^^^^^^^^^^
  File "C:\Users\as222\flask_project1\venv\Lib\site-packages\sqlalchemy\engine\base.py", line 1983, in _exec_single_context
    self._handle_dbapi_exception(
  File "C:\Users\as222\flask_project1\venv\Lib\site-packages\sqlalchemy\engine\base.py", line 2325, in _handle_dbapi_exception
    raise sqlalchemy_exception.with_traceback(exc_info[2]) from e
  File "C:\Users\as222\flask_project1\venv\Lib\site-packages\sqlalchemy\engine\base.py", line 1964, in _exec_single_context
    self.dialect.do_execute(
  File "C:\Users\as222\flask_project1\venv\Lib\site-packages\sqlalchemy\engine\default.py", line 747, in do_execute
    cursor.execute(statement, parameters)
  File "C:\Users\as222\flask_project1\venv\Lib\site-packages\pymysql\cursors.py", line 148, in execute
    result = self._query(query)
             ^^^^^^^^^^^^^^^^^^
  File "C:\Users\as222\flask_project1\venv\Lib\site-packages\pymysql\cursors.py", line 310, in _query
    conn.query(q)
  File "C:\Users\as222\flask_project1\venv\Lib\site-packages\pymysql\connections.py", line 548, in query
    self._affected_rows = self._read_query_result(unbuffered=unbuffered)
                          ^^^^^^^^^^^^^^^^^^^^^^^^^^^^^^^^^^^^^^^^^^^^^^
  File "C:\Users\as222\flask_project1\venv\Lib\site-packages\pymysql\connections.py", line 775, in _read_query_result
    result.read()
  File "C:\Users\as222\flask_project1\venv\Lib\site-packages\pymysql\connections.py", line 1156, in read
    first_packet = self.connection._read_packet()
                   ^^^^^^^^^^^^^^^^^^^^^^^^^^^^^^
  File "C:\Users\as222\flask_project1\venv\Lib\site-packages\pymysql\connections.py", line 725, in _read_packet
    packet.raise_for_error()
  File "C:\Users\as222\flask_project1\venv\Lib\site-packages\pymysql\protocol.py", line 221, in raise_for_error
    err.raise_mysql_exception(self._data)
  File "C:\Users\as222\flask_project1\venv\Lib\site-packages\pymysql\err.py", line 143, in raise_mysql_exception
    raise errorclass(errno, errval)
sqlalchemy.exc.OperationalError: (pymysql.err.OperationalError) (1054, "Unknown column 'photos.Special_Filename' in 'field list'")
[SQL: SELECT photos.id AS photos_id, photos.`Name` AS `photos_Name`, photos.`Filename` AS `photos_Filename`, photos.`Special_Filename` AS `photos_Special_Filename`, photos.`Description` AS `photos_Description`, photos.`Upload_time` AS `photos_Upload_time` 
FROM photos 
WHERE photos.id = %(id_1)s 
 LIMIT %(param_1)s]
[parameters: {'id_1': 1, 'param_1': 1}]
(Background on this error at: https://sqlalche.me/e/20/e3q8)
2023-03-21 19:31:09,805 - apps - ERROR - Exception on /photo [GET]
Traceback (most recent call last):
  File "C:\Users\as222\flask_project1\venv\Lib\site-packages\flask\app.py", line 2528, in wsgi_app
    response = self.full_dispatch_request()
               ^^^^^^^^^^^^^^^^^^^^^^^^^^^^
  File "C:\Users\as222\flask_project1\venv\Lib\site-packages\flask\app.py", line 1825, in full_dispatch_request
    rv = self.handle_user_exception(e)
         ^^^^^^^^^^^^^^^^^^^^^^^^^^^^^
  File "C:\Users\as222\flask_project1\venv\Lib\site-packages\flask\app.py", line 1823, in full_dispatch_request
    rv = self.dispatch_request()
         ^^^^^^^^^^^^^^^^^^^^^^^
  File "C:\Users\as222\flask_project1\venv\Lib\site-packages\flask\app.py", line 1799, in dispatch_request
    return self.ensure_sync(self.view_functions[rule.endpoint])(**view_args)
           ^^^^^^^^^^^^^^^^^^^^^^^^^^^^^^^^^^^^^^^^^^^^^^^^^^^^^^^^^^^^^^^^^
  File "C:\Users\as222\flask_project2\router.py", line 163, in view_photo
    return render_template("show_photos.html",photos=photos)
           ^^^^^^^^^^^^^^^^^^^^^^^^^^^^^^^^^^^^^^^^^^^^^^^^^
  File "C:\Users\as222\flask_project1\venv\Lib\site-packages\flask\templating.py", line 146, in render_template
    template = app.jinja_env.get_or_select_template(template_name_or_list)
               ^^^^^^^^^^^^^^^^^^^^^^^^^^^^^^^^^^^^^^^^^^^^^^^^^^^^^^^^^^^
  File "C:\Users\as222\flask_project1\venv\Lib\site-packages\jinja2\environment.py", line 1081, in get_or_select_template
    return self.get_template(template_name_or_list, parent, globals)
           ^^^^^^^^^^^^^^^^^^^^^^^^^^^^^^^^^^^^^^^^^^^^^^^^^^^^^^^^^
  File "C:\Users\as222\flask_project1\venv\Lib\site-packages\jinja2\environment.py", line 1010, in get_template
    return self._load_template(name, globals)
           ^^^^^^^^^^^^^^^^^^^^^^^^^^^^^^^^^^
  File "C:\Users\as222\flask_project1\venv\Lib\site-packages\jinja2\environment.py", line 969, in _load_template
    template = self.loader.load(self, name, self.make_globals(globals))
               ^^^^^^^^^^^^^^^^^^^^^^^^^^^^^^^^^^^^^^^^^^^^^^^^^^^^^^^^
  File "C:\Users\as222\flask_project1\venv\Lib\site-packages\jinja2\loaders.py", line 126, in load
    source, filename, uptodate = self.get_source(environment, name)
                                 ^^^^^^^^^^^^^^^^^^^^^^^^^^^^^^^^^^
  File "C:\Users\as222\flask_project1\venv\Lib\site-packages\flask\templating.py", line 62, in get_source
    return self._get_source_fast(environment, template)
           ^^^^^^^^^^^^^^^^^^^^^^^^^^^^^^^^^^^^^^^^^^^^
  File "C:\Users\as222\flask_project1\venv\Lib\site-packages\flask\templating.py", line 98, in _get_source_fast
    raise TemplateNotFound(template)
jinja2.exceptions.TemplateNotFound: show_photos.html
2023-03-21 19:31:24,046 - apps - ERROR - Exception on /photo [GET]
Traceback (most recent call last):
  File "C:\Users\as222\flask_project1\venv\Lib\site-packages\flask\app.py", line 2528, in wsgi_app
    response = self.full_dispatch_request()
               ^^^^^^^^^^^^^^^^^^^^^^^^^^^^
  File "C:\Users\as222\flask_project1\venv\Lib\site-packages\flask\app.py", line 1825, in full_dispatch_request
    rv = self.handle_user_exception(e)
         ^^^^^^^^^^^^^^^^^^^^^^^^^^^^^
  File "C:\Users\as222\flask_project1\venv\Lib\site-packages\flask\app.py", line 1823, in full_dispatch_request
    rv = self.dispatch_request()
         ^^^^^^^^^^^^^^^^^^^^^^^
  File "C:\Users\as222\flask_project1\venv\Lib\site-packages\flask\app.py", line 1799, in dispatch_request
    return self.ensure_sync(self.view_functions[rule.endpoint])(**view_args)
           ^^^^^^^^^^^^^^^^^^^^^^^^^^^^^^^^^^^^^^^^^^^^^^^^^^^^^^^^^^^^^^^^^
  File "C:\Users\as222\flask_project2\router.py", line 163, in view_photo
    return render_template("user/show_photos.html",photos=photos)
           ^^^^^^^^^^^^^^^^^^^^^^^^^^^^^^^^^^^^^^^^^^^^^^^^^^^^^^
  File "C:\Users\as222\flask_project1\venv\Lib\site-packages\flask\templating.py", line 147, in render_template
    return _render(app, template, context)
           ^^^^^^^^^^^^^^^^^^^^^^^^^^^^^^^
  File "C:\Users\as222\flask_project1\venv\Lib\site-packages\flask\templating.py", line 130, in _render
    rv = template.render(context)
         ^^^^^^^^^^^^^^^^^^^^^^^^
  File "C:\Users\as222\flask_project1\venv\Lib\site-packages\jinja2\environment.py", line 1301, in render
    self.environment.handle_exception()
  File "C:\Users\as222\flask_project1\venv\Lib\site-packages\jinja2\environment.py", line 936, in handle_exception
    raise rewrite_traceback_stack(source=source)
  File "C:\Users\as222\flask_project2\apps\templates\user\show_photos.html", line 1, in top-level template code
    {% extends "user/layout.html" %}
    ^^^^^^^^^^^^^^^^^^^^^^^^^
  File "C:\Users\as222\flask_project2\apps\templates\user\layout.html", line 13, in top-level template code
    {% block body %} {% endblock %}
    ^^^^^^^^^^^^^^^^^^^^^^^^^
  File "C:\Users\as222\flask_project2\apps\templates\user\show_photos.html", line 62, in block 'body'
    <img src="{{ url_for('static/image/upload', filename=photo.Filename) }}" alt="{{ photo.Name }}" width="500px">
    ^^^^^^^^^^^^^^^^^^^^^^^^^
  File "C:\Users\as222\flask_project1\venv\Lib\site-packages\flask\app.py", line 2034, in url_for
    return self.handle_url_build_error(error, endpoint, values)
           ^^^^^^^^^^^^^^^^^^^^^^^^^^^^^^^^^^^^^^^^^^^^^^^^^^^^
  File "C:\Users\as222\flask_project1\venv\Lib\site-packages\flask\app.py", line 2023, in url_for
    rv = url_adapter.build(  # type: ignore[union-attr]
         ^^^^^^^^^^^^^^^^^^^^^^^^^^^^^^^^^^^^^^^^^^^^^^
  File "C:\Users\as222\flask_project1\venv\Lib\site-packages\werkzeug\routing\map.py", line 917, in build
    raise BuildError(endpoint, values, method, self)
werkzeug.routing.exceptions.BuildError: Could not build url for endpoint 'static/image/upload' with values ['filename']. Did you mean 'static' instead?
2023-03-21 19:50:21,207 - apps - ERROR - Exception on /photo [GET]
Traceback (most recent call last):
  File "C:\Users\as222\flask_project1\venv\Lib\site-packages\flask\app.py", line 2528, in wsgi_app
    response = self.full_dispatch_request()
               ^^^^^^^^^^^^^^^^^^^^^^^^^^^^
  File "C:\Users\as222\flask_project1\venv\Lib\site-packages\flask\app.py", line 1825, in full_dispatch_request
    rv = self.handle_user_exception(e)
         ^^^^^^^^^^^^^^^^^^^^^^^^^^^^^
  File "C:\Users\as222\flask_project1\venv\Lib\site-packages\flask\app.py", line 1823, in full_dispatch_request
    rv = self.dispatch_request()
         ^^^^^^^^^^^^^^^^^^^^^^^
  File "C:\Users\as222\flask_project1\venv\Lib\site-packages\flask\app.py", line 1799, in dispatch_request
    return self.ensure_sync(self.view_functions[rule.endpoint])(**view_args)
           ^^^^^^^^^^^^^^^^^^^^^^^^^^^^^^^^^^^^^^^^^^^^^^^^^^^^^^^^^^^^^^^^^
  File "C:\Users\as222\flask_project2\router.py", line 163, in view_photo
    return render_template("user/show_photos.html",photos=photos)
           ^^^^^^^^^^^^^^^^^^^^^^^^^^^^^^^^^^^^^^^^^^^^^^^^^^^^^^
  File "C:\Users\as222\flask_project1\venv\Lib\site-packages\flask\templating.py", line 146, in render_template
    template = app.jinja_env.get_or_select_template(template_name_or_list)
               ^^^^^^^^^^^^^^^^^^^^^^^^^^^^^^^^^^^^^^^^^^^^^^^^^^^^^^^^^^^
  File "C:\Users\as222\flask_project1\venv\Lib\site-packages\jinja2\environment.py", line 1081, in get_or_select_template
    return self.get_template(template_name_or_list, parent, globals)
           ^^^^^^^^^^^^^^^^^^^^^^^^^^^^^^^^^^^^^^^^^^^^^^^^^^^^^^^^^
  File "C:\Users\as222\flask_project1\venv\Lib\site-packages\jinja2\environment.py", line 1010, in get_template
    return self._load_template(name, globals)
           ^^^^^^^^^^^^^^^^^^^^^^^^^^^^^^^^^^
  File "C:\Users\as222\flask_project1\venv\Lib\site-packages\jinja2\environment.py", line 969, in _load_template
    template = self.loader.load(self, name, self.make_globals(globals))
               ^^^^^^^^^^^^^^^^^^^^^^^^^^^^^^^^^^^^^^^^^^^^^^^^^^^^^^^^
  File "C:\Users\as222\flask_project1\venv\Lib\site-packages\jinja2\loaders.py", line 138, in load
    code = environment.compile(source, name, filename)
           ^^^^^^^^^^^^^^^^^^^^^^^^^^^^^^^^^^^^^^^^^^^
  File "C:\Users\as222\flask_project1\venv\Lib\site-packages\jinja2\environment.py", line 768, in compile
    self.handle_exception(source=source_hint)
  File "C:\Users\as222\flask_project1\venv\Lib\site-packages\jinja2\environment.py", line 936, in handle_exception
    raise rewrite_traceback_stack(source=source)
  File "C:\Users\as222\flask_project2\apps\templates\user\show_photos.html", line 63, in template
    <text x="50%" y="50%" fill="#eceeef" dy=".3em">{{ photo.Name }</text>
    ^^^^^^^^^^^^^^^^^^^^^^^^^
jinja2.exceptions.TemplateSyntaxError: unexpected '}'
2023-03-21 19:50:36,872 - apps - ERROR - Exception on /photo [GET]
Traceback (most recent call last):
  File "C:\Users\as222\flask_project1\venv\Lib\site-packages\flask\app.py", line 2528, in wsgi_app
    response = self.full_dispatch_request()
               ^^^^^^^^^^^^^^^^^^^^^^^^^^^^
  File "C:\Users\as222\flask_project1\venv\Lib\site-packages\flask\app.py", line 1825, in full_dispatch_request
    rv = self.handle_user_exception(e)
         ^^^^^^^^^^^^^^^^^^^^^^^^^^^^^
  File "C:\Users\as222\flask_project1\venv\Lib\site-packages\flask\app.py", line 1823, in full_dispatch_request
    rv = self.dispatch_request()
         ^^^^^^^^^^^^^^^^^^^^^^^
  File "C:\Users\as222\flask_project1\venv\Lib\site-packages\flask\app.py", line 1799, in dispatch_request
    return self.ensure_sync(self.view_functions[rule.endpoint])(**view_args)
           ^^^^^^^^^^^^^^^^^^^^^^^^^^^^^^^^^^^^^^^^^^^^^^^^^^^^^^^^^^^^^^^^^
  File "C:\Users\as222\flask_project2\router.py", line 163, in view_photo
    return render_template("user/show_photos.html",photos=photos)
           ^^^^^^^^^^^^^^^^^^^^^^^^^^^^^^^^^^^^^^^^^^^^^^^^^^^^^^
  File "C:\Users\as222\flask_project1\venv\Lib\site-packages\flask\templating.py", line 146, in render_template
    template = app.jinja_env.get_or_select_template(template_name_or_list)
               ^^^^^^^^^^^^^^^^^^^^^^^^^^^^^^^^^^^^^^^^^^^^^^^^^^^^^^^^^^^
  File "C:\Users\as222\flask_project1\venv\Lib\site-packages\jinja2\environment.py", line 1081, in get_or_select_template
    return self.get_template(template_name_or_list, parent, globals)
           ^^^^^^^^^^^^^^^^^^^^^^^^^^^^^^^^^^^^^^^^^^^^^^^^^^^^^^^^^
  File "C:\Users\as222\flask_project1\venv\Lib\site-packages\jinja2\environment.py", line 1010, in get_template
    return self._load_template(name, globals)
           ^^^^^^^^^^^^^^^^^^^^^^^^^^^^^^^^^^
  File "C:\Users\as222\flask_project1\venv\Lib\site-packages\jinja2\environment.py", line 969, in _load_template
    template = self.loader.load(self, name, self.make_globals(globals))
               ^^^^^^^^^^^^^^^^^^^^^^^^^^^^^^^^^^^^^^^^^^^^^^^^^^^^^^^^
  File "C:\Users\as222\flask_project1\venv\Lib\site-packages\jinja2\loaders.py", line 138, in load
    code = environment.compile(source, name, filename)
           ^^^^^^^^^^^^^^^^^^^^^^^^^^^^^^^^^^^^^^^^^^^
  File "C:\Users\as222\flask_project1\venv\Lib\site-packages\jinja2\environment.py", line 768, in compile
    self.handle_exception(source=source_hint)
  File "C:\Users\as222\flask_project1\venv\Lib\site-packages\jinja2\environment.py", line 936, in handle_exception
    raise rewrite_traceback_stack(source=source)
  File "C:\Users\as222\flask_project2\apps\templates\user\show_photos.html", line 81, in template
    {% endblock %}
jinja2.exceptions.TemplateSyntaxError: Encountered unknown tag 'endblock'. You probably made a nesting mistake. Jinja is expecting this tag, but currently looking for 'endfor' or 'else'. The innermost block that needs to be closed is 'for'.
2023-03-21 21:10:50,635 - apps - ERROR - Exception on /photo/delete/1 [GET]
Traceback (most recent call last):
  File "C:\Users\as222\flask_project1\venv\Lib\site-packages\flask\app.py", line 2528, in wsgi_app
    response = self.full_dispatch_request()
               ^^^^^^^^^^^^^^^^^^^^^^^^^^^^
  File "C:\Users\as222\flask_project1\venv\Lib\site-packages\flask\app.py", line 1825, in full_dispatch_request
    rv = self.handle_user_exception(e)
         ^^^^^^^^^^^^^^^^^^^^^^^^^^^^^
  File "C:\Users\as222\flask_project1\venv\Lib\site-packages\flask\app.py", line 1823, in full_dispatch_request
    rv = self.dispatch_request()
         ^^^^^^^^^^^^^^^^^^^^^^^
  File "C:\Users\as222\flask_project1\venv\Lib\site-packages\flask\app.py", line 1799, in dispatch_request
    return self.ensure_sync(self.view_functions[rule.endpoint])(**view_args)
           ^^^^^^^^^^^^^^^^^^^^^^^^^^^^^^^^^^^^^^^^^^^^^^^^^^^^^^^^^^^^^^^^^
  File "C:\Users\as222\flask_project2\router.py", line 164, in photo_delete_id
    return views.Delete_photo_id(photo_id)
           ^^^^^^^^^^^^^^^^^^^^^^^^^^^^^^^
  File "C:\Users\as222\flask_project2\apps\views\user.py", line 168, in Delete_photo_id
    photo=Photos.query.get_or_404(id=photo_id)
          ^^^^^^^^^^^^^^^^^^^^^^^^^^^^^^^^^^^^
TypeError: Query.get_or_404() got an unexpected keyword argument 'id'
2023-03-21 21:11:54,793 - apps - ERROR - Exception on /photo/delete/1 [GET]
Traceback (most recent call last):
  File "C:\Users\as222\flask_project1\venv\Lib\site-packages\flask\app.py", line 2528, in wsgi_app
    response = self.full_dispatch_request()
               ^^^^^^^^^^^^^^^^^^^^^^^^^^^^
  File "C:\Users\as222\flask_project1\venv\Lib\site-packages\flask\app.py", line 1825, in full_dispatch_request
    rv = self.handle_user_exception(e)
         ^^^^^^^^^^^^^^^^^^^^^^^^^^^^^
  File "C:\Users\as222\flask_project1\venv\Lib\site-packages\flask\app.py", line 1823, in full_dispatch_request
    rv = self.dispatch_request()
         ^^^^^^^^^^^^^^^^^^^^^^^
  File "C:\Users\as222\flask_project1\venv\Lib\site-packages\flask\app.py", line 1799, in dispatch_request
    return self.ensure_sync(self.view_functions[rule.endpoint])(**view_args)
           ^^^^^^^^^^^^^^^^^^^^^^^^^^^^^^^^^^^^^^^^^^^^^^^^^^^^^^^^^^^^^^^^^
  File "C:\Users\as222\flask_project2\router.py", line 164, in photo_delete_id
    return views.Delete_photo_id(photo_id)
           ^^^^^^^^^^^^^^^^^^^^^^^^^^^^^^^
  File "C:\Users\as222\flask_project2\apps\views\user.py", line 170, in Delete_photo_id
    db.commit()
    ^^^^^^^^^
  File "C:\Users\as222\flask_project1\venv\Lib\site-packages\flask_sqlalchemy\extension.py", line 1005, in __getattr__
    raise AttributeError(name)
AttributeError: commit
2023-03-21 21:14:37,771 - apps - ERROR - Exception on /photo/delete/1 [GET]
Traceback (most recent call last):
  File "C:\Users\as222\flask_project1\venv\Lib\site-packages\flask\app.py", line 2528, in wsgi_app
    response = self.full_dispatch_request()
               ^^^^^^^^^^^^^^^^^^^^^^^^^^^^
  File "C:\Users\as222\flask_project1\venv\Lib\site-packages\flask\app.py", line 1825, in full_dispatch_request
    rv = self.handle_user_exception(e)
         ^^^^^^^^^^^^^^^^^^^^^^^^^^^^^
  File "C:\Users\as222\flask_project1\venv\Lib\site-packages\flask\app.py", line 1823, in full_dispatch_request
    rv = self.dispatch_request()
         ^^^^^^^^^^^^^^^^^^^^^^^
  File "C:\Users\as222\flask_project1\venv\Lib\site-packages\flask\app.py", line 1799, in dispatch_request
    return self.ensure_sync(self.view_functions[rule.endpoint])(**view_args)
           ^^^^^^^^^^^^^^^^^^^^^^^^^^^^^^^^^^^^^^^^^^^^^^^^^^^^^^^^^^^^^^^^^
  File "C:\Users\as222\flask_project2\router.py", line 164, in photo_delete_id
    return views.Delete_photo_id(photo_id)
           ^^^^^^^^^^^^^^^^^^^^^^^^^^^^^^^
  File "C:\Users\as222\flask_project2\apps\views\user.py", line 171, in Delete_photo_id
    os.path.removen(app.config['UPLOAD_FOLDER'],photo_to_delete.Filename)
    ^^^^^^^^^^^^^^^
AttributeError: module 'ntpath' has no attribute 'removen'
2023-03-21 21:25:22,986 - apps - ERROR - Exception on /photo/delete/1 [GET]
Traceback (most recent call last):
  File "C:\Users\as222\flask_project2\apps\views\user.py", line 169, in Delete_photo_id
    photo_to_delete=Photos.query.get_or_404(photo_id)
                    ^^^^^^^^^^^^^^^^^^^^^^^^^^^^^^^^^
  File "C:\Users\as222\flask_project1\venv\Lib\site-packages\flask_sqlalchemy\query.py", line 34, in get_or_404
    abort(404, description=description)
  File "C:\Users\as222\flask_project1\venv\Lib\site-packages\flask\helpers.py", line 310, in abort
    current_app.aborter(code, *args, **kwargs)
  File "C:\Users\as222\flask_project1\venv\Lib\site-packages\werkzeug\exceptions.py", line 864, in __call__
    raise self.mapping[code](*args, **kwargs)
werkzeug.exceptions.NotFound: 404 Not Found: The requested URL was not found on the server. If you entered the URL manually please check your spelling and try again.

During handling of the above exception, another exception occurred:

Traceback (most recent call last):
  File "C:\Users\as222\flask_project1\venv\Lib\site-packages\flask\app.py", line 2528, in wsgi_app
    response = self.full_dispatch_request()
               ^^^^^^^^^^^^^^^^^^^^^^^^^^^^
  File "C:\Users\as222\flask_project1\venv\Lib\site-packages\flask\app.py", line 1825, in full_dispatch_request
    rv = self.handle_user_exception(e)
         ^^^^^^^^^^^^^^^^^^^^^^^^^^^^^
  File "C:\Users\as222\flask_project1\venv\Lib\site-packages\flask\app.py", line 1823, in full_dispatch_request
    rv = self.dispatch_request()
         ^^^^^^^^^^^^^^^^^^^^^^^
  File "C:\Users\as222\flask_project1\venv\Lib\site-packages\flask\app.py", line 1799, in dispatch_request
    return self.ensure_sync(self.view_functions[rule.endpoint])(**view_args)
           ^^^^^^^^^^^^^^^^^^^^^^^^^^^^^^^^^^^^^^^^^^^^^^^^^^^^^^^^^^^^^^^^^
  File "C:\Users\as222\flask_project2\router.py", line 164, in photo_delete_id
    return views.Delete_photo_id(photo_id)
           ^^^^^^^^^^^^^^^^^^^^^^^^^^^^^^^
  File "C:\Users\as222\flask_project2\apps\views\user.py", line 178, in Delete_photo_id
    return render_template("user/show-post.html",posts=posts)
                                                       ^^^^^
NameError: name 'posts' is not defined
2023-03-21 21:48:43,196 - apps - ERROR - Exception on /photo [GET]
Traceback (most recent call last):
  File "C:\Users\as222\flask_project1\venv\Lib\site-packages\flask\app.py", line 2528, in wsgi_app
    response = self.full_dispatch_request()
               ^^^^^^^^^^^^^^^^^^^^^^^^^^^^
  File "C:\Users\as222\flask_project1\venv\Lib\site-packages\flask\app.py", line 1825, in full_dispatch_request
    rv = self.handle_user_exception(e)
         ^^^^^^^^^^^^^^^^^^^^^^^^^^^^^
  File "C:\Users\as222\flask_project1\venv\Lib\site-packages\flask\app.py", line 1823, in full_dispatch_request
    rv = self.dispatch_request()
         ^^^^^^^^^^^^^^^^^^^^^^^
  File "C:\Users\as222\flask_project1\venv\Lib\site-packages\flask\app.py", line 1799, in dispatch_request
    return self.ensure_sync(self.view_functions[rule.endpoint])(**view_args)
           ^^^^^^^^^^^^^^^^^^^^^^^^^^^^^^^^^^^^^^^^^^^^^^^^^^^^^^^^^^^^^^^^^
  File "C:\Users\as222\flask_project2\router.py", line 173, in view_photo
    return render_template("user/show_photos.html",photos=photos)
           ^^^^^^^^^^^^^^^^^^^^^^^^^^^^^^^^^^^^^^^^^^^^^^^^^^^^^^
  File "C:\Users\as222\flask_project1\venv\Lib\site-packages\flask\templating.py", line 147, in render_template
    return _render(app, template, context)
           ^^^^^^^^^^^^^^^^^^^^^^^^^^^^^^^
  File "C:\Users\as222\flask_project1\venv\Lib\site-packages\flask\templating.py", line 130, in _render
    rv = template.render(context)
         ^^^^^^^^^^^^^^^^^^^^^^^^
  File "C:\Users\as222\flask_project1\venv\Lib\site-packages\jinja2\environment.py", line 1301, in render
    self.environment.handle_exception()
  File "C:\Users\as222\flask_project1\venv\Lib\site-packages\jinja2\environment.py", line 936, in handle_exception
    raise rewrite_traceback_stack(source=source)
  File "C:\Users\as222\flask_project2\apps\templates\user\show_photos.html", line 1, in top-level template code
    {% extends "user/layout.html" %}
    ^^^^^^^^^^^^^^^^^^^^^^^^^
  File "C:\Users\as222\flask_project2\apps\templates\user\layout.html", line 67, in top-level template code
    {% block body %} {% endblock %}
    ^^^^^^^^^^^^^^^^^^^^^^^^^
  File "C:\Users\as222\flask_project2\apps\templates\user\show_photos.html", line 69, in block 'body'
    <a type="button" class="btn btn-sm btn-outline-secondary" href="{{url_for('photo_delete_id',photo_id=photo.id)}}" >Delete</a>
    ^^^^^^^^^^^^^^^^^^^^^^^^^
  File "C:\Users\as222\flask_project1\venv\Lib\site-packages\flask\app.py", line 2034, in url_for
    return self.handle_url_build_error(error, endpoint, values)
           ^^^^^^^^^^^^^^^^^^^^^^^^^^^^^^^^^^^^^^^^^^^^^^^^^^^^
  File "C:\Users\as222\flask_project1\venv\Lib\site-packages\flask\app.py", line 2023, in url_for
    rv = url_adapter.build(  # type: ignore[union-attr]
         ^^^^^^^^^^^^^^^^^^^^^^^^^^^^^^^^^^^^^^^^^^^^^^
  File "C:\Users\as222\flask_project1\venv\Lib\site-packages\werkzeug\routing\map.py", line 917, in build
    raise BuildError(endpoint, values, method, self)
werkzeug.routing.exceptions.BuildError: Could not build url for endpoint 'photo_delete_id' with values ['photo_id']. Did you forget to specify values ['id']?
2023-03-22 20:45:06,469 - apps - ERROR - Exception on /photo [GET]
Traceback (most recent call last):
  File "C:\Users\as222\flask_project1\venv\Lib\site-packages\flask\app.py", line 2528, in wsgi_app
    response = self.full_dispatch_request()
               ^^^^^^^^^^^^^^^^^^^^^^^^^^^^
  File "C:\Users\as222\flask_project1\venv\Lib\site-packages\flask\app.py", line 1825, in full_dispatch_request
    rv = self.handle_user_exception(e)
         ^^^^^^^^^^^^^^^^^^^^^^^^^^^^^
  File "C:\Users\as222\flask_project1\venv\Lib\site-packages\flask\app.py", line 1823, in full_dispatch_request
    rv = self.dispatch_request()
         ^^^^^^^^^^^^^^^^^^^^^^^
  File "C:\Users\as222\flask_project1\venv\Lib\site-packages\flask\app.py", line 1799, in dispatch_request
    return self.ensure_sync(self.view_functions[rule.endpoint])(**view_args)
           ^^^^^^^^^^^^^^^^^^^^^^^^^^^^^^^^^^^^^^^^^^^^^^^^^^^^^^^^^^^^^^^^^
  File "C:\Users\as222\flask_project2\router.py", line 173, in view_photo
    return render_template("user/show_photos.html",photos=photos)
           ^^^^^^^^^^^^^^^^^^^^^^^^^^^^^^^^^^^^^^^^^^^^^^^^^^^^^^
  File "C:\Users\as222\flask_project1\venv\Lib\site-packages\flask\templating.py", line 146, in render_template
    template = app.jinja_env.get_or_select_template(template_name_or_list)
               ^^^^^^^^^^^^^^^^^^^^^^^^^^^^^^^^^^^^^^^^^^^^^^^^^^^^^^^^^^^
  File "C:\Users\as222\flask_project1\venv\Lib\site-packages\jinja2\environment.py", line 1081, in get_or_select_template
    return self.get_template(template_name_or_list, parent, globals)
           ^^^^^^^^^^^^^^^^^^^^^^^^^^^^^^^^^^^^^^^^^^^^^^^^^^^^^^^^^
  File "C:\Users\as222\flask_project1\venv\Lib\site-packages\jinja2\environment.py", line 1010, in get_template
    return self._load_template(name, globals)
           ^^^^^^^^^^^^^^^^^^^^^^^^^^^^^^^^^^
  File "C:\Users\as222\flask_project1\venv\Lib\site-packages\jinja2\environment.py", line 969, in _load_template
    template = self.loader.load(self, name, self.make_globals(globals))
               ^^^^^^^^^^^^^^^^^^^^^^^^^^^^^^^^^^^^^^^^^^^^^^^^^^^^^^^^
  File "C:\Users\as222\flask_project1\venv\Lib\site-packages\jinja2\loaders.py", line 138, in load
    code = environment.compile(source, name, filename)
           ^^^^^^^^^^^^^^^^^^^^^^^^^^^^^^^^^^^^^^^^^^^
  File "C:\Users\as222\flask_project1\venv\Lib\site-packages\jinja2\environment.py", line 768, in compile
    self.handle_exception(source=source_hint)
  File "C:\Users\as222\flask_project1\venv\Lib\site-packages\jinja2\environment.py", line 936, in handle_exception
    raise rewrite_traceback_stack(source=source)
  File "C:\Users\as222\flask_project2\apps\templates\user\show_photos.html", line 77, in template
    {% endfor %}
jinja2.exceptions.TemplateSyntaxError: Encountered unknown tag 'endfor'. You probably made a nesting mistake. Jinja is expecting this tag, but currently looking for 'elif' or 'else' or 'endif'. The innermost block that needs to be closed is 'if'.
2023-03-22 21:03:11,666 - apps - ERROR - Exception on /photo/delete/5 [GET]
Traceback (most recent call last):
  File "C:\Users\as222\flask_project1\venv\Lib\site-packages\flask\app.py", line 2528, in wsgi_app
    response = self.full_dispatch_request()
               ^^^^^^^^^^^^^^^^^^^^^^^^^^^^
  File "C:\Users\as222\flask_project1\venv\Lib\site-packages\flask\app.py", line 1825, in full_dispatch_request
    rv = self.handle_user_exception(e)
         ^^^^^^^^^^^^^^^^^^^^^^^^^^^^^
  File "C:\Users\as222\flask_project1\venv\Lib\site-packages\flask\app.py", line 1823, in full_dispatch_request
    rv = self.dispatch_request()
         ^^^^^^^^^^^^^^^^^^^^^^^
  File "C:\Users\as222\flask_project1\venv\Lib\site-packages\flask\app.py", line 1799, in dispatch_request
    return self.ensure_sync(self.view_functions[rule.endpoint])(**view_args)
           ^^^^^^^^^^^^^^^^^^^^^^^^^^^^^^^^^^^^^^^^^^^^^^^^^^^^^^^^^^^^^^^^^
  File "C:\Users\as222\flask_project2\router.py", line 164, in photo_delete_id
    return views.Delete_photo_id(id)
           ^^^^^^^^^^^^^^^^^^^^^^^^^
  File "C:\Users\as222\flask_project2\apps\views\user.py", line 170, in Delete_photo_id
    if current_user.id==photo_to_delete.Photoer.id:
                        ^^^^^^^^^^^^^^^^^^^^^^^^^^
AttributeError: 'NoneType' object has no attribute 'id'
2023-03-22 21:26:07,833 - apps - ERROR - Exception on /photo/delete/5 [GET]
Traceback (most recent call last):
  File "C:\Users\as222\flask_project1\venv\Lib\site-packages\flask\app.py", line 2528, in wsgi_app
    response = self.full_dispatch_request()
               ^^^^^^^^^^^^^^^^^^^^^^^^^^^^
  File "C:\Users\as222\flask_project1\venv\Lib\site-packages\flask\app.py", line 1825, in full_dispatch_request
    rv = self.handle_user_exception(e)
         ^^^^^^^^^^^^^^^^^^^^^^^^^^^^^
  File "C:\Users\as222\flask_project1\venv\Lib\site-packages\flask\app.py", line 1823, in full_dispatch_request
    rv = self.dispatch_request()
         ^^^^^^^^^^^^^^^^^^^^^^^
  File "C:\Users\as222\flask_project1\venv\Lib\site-packages\flask\app.py", line 1799, in dispatch_request
    return self.ensure_sync(self.view_functions[rule.endpoint])(**view_args)
           ^^^^^^^^^^^^^^^^^^^^^^^^^^^^^^^^^^^^^^^^^^^^^^^^^^^^^^^^^^^^^^^^^
  File "C:\Users\as222\flask_project2\router.py", line 164, in photo_delete_id
    return views.Delete_photo_id(id)
           ^^^^^^^^^^^^^^^^^^^^^^^^^
  File "C:\Users\as222\flask_project2\apps\views\user.py", line 169, in Delete_photo_id
    if current_user.id==photo_to_delete.Photoer.id:
                        ^^^^^^^^^^^^^^^^^^^^^^^^^^
AttributeError: 'NoneType' object has no attribute 'id'
2023-03-22 21:30:35,584 - apps - ERROR - Exception on /photo/delete/5 [GET]
Traceback (most recent call last):
  File "C:\Users\as222\flask_project1\venv\Lib\site-packages\flask\app.py", line 2528, in wsgi_app
    response = self.full_dispatch_request()
               ^^^^^^^^^^^^^^^^^^^^^^^^^^^^
  File "C:\Users\as222\flask_project1\venv\Lib\site-packages\flask\app.py", line 1825, in full_dispatch_request
    rv = self.handle_user_exception(e)
         ^^^^^^^^^^^^^^^^^^^^^^^^^^^^^
  File "C:\Users\as222\flask_project1\venv\Lib\site-packages\flask\app.py", line 1823, in full_dispatch_request
    rv = self.dispatch_request()
         ^^^^^^^^^^^^^^^^^^^^^^^
  File "C:\Users\as222\flask_project1\venv\Lib\site-packages\flask\app.py", line 1799, in dispatch_request
    return self.ensure_sync(self.view_functions[rule.endpoint])(**view_args)
           ^^^^^^^^^^^^^^^^^^^^^^^^^^^^^^^^^^^^^^^^^^^^^^^^^^^^^^^^^^^^^^^^^
  File "C:\Users\as222\flask_project2\router.py", line 164, in photo_delete_id
    return views.Delete_photo_id(id)
           ^^^^^^^^^^^^^^^^^^^^^^^^^
  File "C:\Users\as222\flask_project2\apps\views\user.py", line 169, in Delete_photo_id
    if current_user.id==photo_to_delete.Photoer.id:
                        ^^^^^^^^^^^^^^^^^^^^^^^^^^
AttributeError: 'NoneType' object has no attribute 'id'
2023-03-22 21:36:23,002 - apps - ERROR - Exception on /photo [GET]
Traceback (most recent call last):
  File "C:\Users\as222\flask_project1\venv\Lib\site-packages\flask\app.py", line 2528, in wsgi_app
    response = self.full_dispatch_request()
               ^^^^^^^^^^^^^^^^^^^^^^^^^^^^
  File "C:\Users\as222\flask_project1\venv\Lib\site-packages\flask\app.py", line 1825, in full_dispatch_request
    rv = self.handle_user_exception(e)
         ^^^^^^^^^^^^^^^^^^^^^^^^^^^^^
  File "C:\Users\as222\flask_project1\venv\Lib\site-packages\flask\app.py", line 1823, in full_dispatch_request
    rv = self.dispatch_request()
         ^^^^^^^^^^^^^^^^^^^^^^^
  File "C:\Users\as222\flask_project1\venv\Lib\site-packages\flask\app.py", line 1799, in dispatch_request
    return self.ensure_sync(self.view_functions[rule.endpoint])(**view_args)
           ^^^^^^^^^^^^^^^^^^^^^^^^^^^^^^^^^^^^^^^^^^^^^^^^^^^^^^^^^^^^^^^^^
  File "C:\Users\as222\flask_project2\router.py", line 173, in view_photo
    return render_template("user/show_photos.html",photos=photos)
           ^^^^^^^^^^^^^^^^^^^^^^^^^^^^^^^^^^^^^^^^^^^^^^^^^^^^^^
  File "C:\Users\as222\flask_project1\venv\Lib\site-packages\flask\templating.py", line 147, in render_template
    return _render(app, template, context)
           ^^^^^^^^^^^^^^^^^^^^^^^^^^^^^^^
  File "C:\Users\as222\flask_project1\venv\Lib\site-packages\flask\templating.py", line 130, in _render
    rv = template.render(context)
         ^^^^^^^^^^^^^^^^^^^^^^^^
  File "C:\Users\as222\flask_project1\venv\Lib\site-packages\jinja2\environment.py", line 1301, in render
    self.environment.handle_exception()
  File "C:\Users\as222\flask_project1\venv\Lib\site-packages\jinja2\environment.py", line 936, in handle_exception
    raise rewrite_traceback_stack(source=source)
  File "C:\Users\as222\flask_project2\apps\templates\user\show_photos.html", line 1, in top-level template code
    {% extends "user/layout.html" %}
    ^^^^^^^^^^^^^^^^^^^^^^^^^
  File "C:\Users\as222\flask_project2\apps\templates\user\layout.html", line 67, in top-level template code
    {% block body %} {% endblock %}
    ^^^^^^^^^^^^^^^^^^^^^^^^^
  File "C:\Users\as222\flask_project2\apps\templates\user\show_photos.html", line 66, in block 'body'
    <p class="card-text">{{ photo.Photoer.name }}</p>
    ^^^^^^^^^^^^^^^^^^^^^^^^^
  File "C:\Users\as222\flask_project1\venv\Lib\site-packages\jinja2\environment.py", line 485, in getattr
    return getattr(obj, attribute)
           ^^^^^^^^^^^^^^^^^^^^^^^
jinja2.exceptions.UndefinedError: 'apps.models.user.Photos object' has no attribute 'Photoer'
2023-03-22 21:38:01,852 - apps - ERROR - Exception on /photo [GET]
Traceback (most recent call last):
  File "C:\Users\as222\flask_project1\venv\Lib\site-packages\flask\app.py", line 2528, in wsgi_app
    response = self.full_dispatch_request()
               ^^^^^^^^^^^^^^^^^^^^^^^^^^^^
  File "C:\Users\as222\flask_project1\venv\Lib\site-packages\flask\app.py", line 1825, in full_dispatch_request
    rv = self.handle_user_exception(e)
         ^^^^^^^^^^^^^^^^^^^^^^^^^^^^^
  File "C:\Users\as222\flask_project1\venv\Lib\site-packages\flask\app.py", line 1823, in full_dispatch_request
    rv = self.dispatch_request()
         ^^^^^^^^^^^^^^^^^^^^^^^
  File "C:\Users\as222\flask_project1\venv\Lib\site-packages\flask\app.py", line 1799, in dispatch_request
    return self.ensure_sync(self.view_functions[rule.endpoint])(**view_args)
           ^^^^^^^^^^^^^^^^^^^^^^^^^^^^^^^^^^^^^^^^^^^^^^^^^^^^^^^^^^^^^^^^^
  File "C:\Users\as222\flask_project2\router.py", line 173, in view_photo
    return render_template("user/show_photos.html",photos=photos)
           ^^^^^^^^^^^^^^^^^^^^^^^^^^^^^^^^^^^^^^^^^^^^^^^^^^^^^^
  File "C:\Users\as222\flask_project1\venv\Lib\site-packages\flask\templating.py", line 147, in render_template
    return _render(app, template, context)
           ^^^^^^^^^^^^^^^^^^^^^^^^^^^^^^^
  File "C:\Users\as222\flask_project1\venv\Lib\site-packages\flask\templating.py", line 130, in _render
    rv = template.render(context)
         ^^^^^^^^^^^^^^^^^^^^^^^^
  File "C:\Users\as222\flask_project1\venv\Lib\site-packages\jinja2\environment.py", line 1301, in render
    self.environment.handle_exception()
  File "C:\Users\as222\flask_project1\venv\Lib\site-packages\jinja2\environment.py", line 936, in handle_exception
    raise rewrite_traceback_stack(source=source)
  File "C:\Users\as222\flask_project2\apps\templates\user\show_photos.html", line 1, in top-level template code
    {% extends "user/layout.html" %}
    ^^^^^^^^^^^^^^^^^^^^^^^^^
  File "C:\Users\as222\flask_project2\apps\templates\user\layout.html", line 67, in top-level template code
    {% block body %} {% endblock %}
    ^^^^^^^^^^^^^^^^^^^^^^^^^
  File "C:\Users\as222\flask_project2\apps\templates\user\show_photos.html", line 66, in block 'body'
    <p class="card-text">{{ photo.Photoer.name }}</p>
    ^^^^^^^^^^^^^^^^^^^^^^^^^
  File "C:\Users\as222\flask_project1\venv\Lib\site-packages\jinja2\environment.py", line 485, in getattr
    return getattr(obj, attribute)
           ^^^^^^^^^^^^^^^^^^^^^^^
jinja2.exceptions.UndefinedError: 'apps.models.user.Photos object' has no attribute 'Photoer'
2023-03-22 21:40:36,599 - apps - ERROR - Exception on /photo_uploads [POST]
Traceback (most recent call last):
  File "C:\Users\as222\flask_project1\venv\Lib\site-packages\sqlalchemy\engine\base.py", line 1964, in _exec_single_context
    self.dialect.do_execute(
  File "C:\Users\as222\flask_project1\venv\Lib\site-packages\sqlalchemy\engine\default.py", line 747, in do_execute
    cursor.execute(statement, parameters)
  File "C:\Users\as222\flask_project1\venv\Lib\site-packages\pymysql\cursors.py", line 148, in execute
    result = self._query(query)
             ^^^^^^^^^^^^^^^^^^
  File "C:\Users\as222\flask_project1\venv\Lib\site-packages\pymysql\cursors.py", line 310, in _query
    conn.query(q)
  File "C:\Users\as222\flask_project1\venv\Lib\site-packages\pymysql\connections.py", line 548, in query
    self._affected_rows = self._read_query_result(unbuffered=unbuffered)
                          ^^^^^^^^^^^^^^^^^^^^^^^^^^^^^^^^^^^^^^^^^^^^^^
  File "C:\Users\as222\flask_project1\venv\Lib\site-packages\pymysql\connections.py", line 775, in _read_query_result
    result.read()
  File "C:\Users\as222\flask_project1\venv\Lib\site-packages\pymysql\connections.py", line 1156, in read
    first_packet = self.connection._read_packet()
                   ^^^^^^^^^^^^^^^^^^^^^^^^^^^^^^
  File "C:\Users\as222\flask_project1\venv\Lib\site-packages\pymysql\connections.py", line 725, in _read_packet
    packet.raise_for_error()
  File "C:\Users\as222\flask_project1\venv\Lib\site-packages\pymysql\protocol.py", line 221, in raise_for_error
    err.raise_mysql_exception(self._data)
  File "C:\Users\as222\flask_project1\venv\Lib\site-packages\pymysql\err.py", line 143, in raise_mysql_exception
    raise errorclass(errno, errval)
pymysql.err.IntegrityError: (1048, "Column 'Photoer_id' cannot be null")

The above exception was the direct cause of the following exception:

Traceback (most recent call last):
  File "C:\Users\as222\flask_project1\venv\Lib\site-packages\flask\app.py", line 2528, in wsgi_app
    response = self.full_dispatch_request()
               ^^^^^^^^^^^^^^^^^^^^^^^^^^^^
  File "C:\Users\as222\flask_project1\venv\Lib\site-packages\flask\app.py", line 1825, in full_dispatch_request
    rv = self.handle_user_exception(e)
         ^^^^^^^^^^^^^^^^^^^^^^^^^^^^^
  File "C:\Users\as222\flask_project1\venv\Lib\site-packages\flask\app.py", line 1823, in full_dispatch_request
    rv = self.dispatch_request()
         ^^^^^^^^^^^^^^^^^^^^^^^
  File "C:\Users\as222\flask_project1\venv\Lib\site-packages\flask\app.py", line 1799, in dispatch_request
    return self.ensure_sync(self.view_functions[rule.endpoint])(**view_args)
           ^^^^^^^^^^^^^^^^^^^^^^^^^^^^^^^^^^^^^^^^^^^^^^^^^^^^^^^^^^^^^^^^^
  File "C:\Users\as222\flask_project2\router.py", line 140, in upload_photos
    return views.Upload_photo()
           ^^^^^^^^^^^^^^^^^^^^
  File "C:\Users\as222\flask_project2\apps\views\user.py", line 162, in Upload_photo
    db.session.commit()
  File "C:\Users\as222\flask_project1\venv\Lib\site-packages\sqlalchemy\orm\scoping.py", line 538, in commit
    return self._proxied.commit()
           ^^^^^^^^^^^^^^^^^^^^^^
  File "C:\Users\as222\flask_project1\venv\Lib\site-packages\sqlalchemy\orm\session.py", line 1903, in commit
    trans.commit(_to_root=True)
  File "<string>", line 2, in commit
  File "C:\Users\as222\flask_project1\venv\Lib\site-packages\sqlalchemy\orm\state_changes.py", line 137, in _go
    ret_value = fn(self, *arg, **kw)
                ^^^^^^^^^^^^^^^^^^^^
  File "C:\Users\as222\flask_project1\venv\Lib\site-packages\sqlalchemy\orm\session.py", line 1218, in commit
    self._prepare_impl()
  File "<string>", line 2, in _prepare_impl
  File "C:\Users\as222\flask_project1\venv\Lib\site-packages\sqlalchemy\orm\state_changes.py", line 137, in _go
    ret_value = fn(self, *arg, **kw)
                ^^^^^^^^^^^^^^^^^^^^
  File "C:\Users\as222\flask_project1\venv\Lib\site-packages\sqlalchemy\orm\session.py", line 1193, in _prepare_impl
    self.session.flush()
  File "C:\Users\as222\flask_project1\venv\Lib\site-packages\sqlalchemy\orm\session.py", line 4153, in flush
    self._flush(objects)
  File "C:\Users\as222\flask_project1\venv\Lib\site-packages\sqlalchemy\orm\session.py", line 4289, in _flush
    with util.safe_reraise():
  File "C:\Users\as222\flask_project1\venv\Lib\site-packages\sqlalchemy\util\langhelpers.py", line 147, in __exit__
    raise exc_value.with_traceback(exc_tb)
  File "C:\Users\as222\flask_project1\venv\Lib\site-packages\sqlalchemy\orm\session.py", line 4250, in _flush
    flush_context.execute()
  File "C:\Users\as222\flask_project1\venv\Lib\site-packages\sqlalchemy\orm\unitofwork.py", line 467, in execute
    rec.execute(self)
  File "C:\Users\as222\flask_project1\venv\Lib\site-packages\sqlalchemy\orm\unitofwork.py", line 644, in execute
    util.preloaded.orm_persistence.save_obj(
  File "C:\Users\as222\flask_project1\venv\Lib\site-packages\sqlalchemy\orm\persistence.py", line 93, in save_obj
    _emit_insert_statements(
  File "C:\Users\as222\flask_project1\venv\Lib\site-packages\sqlalchemy\orm\persistence.py", line 1188, in _emit_insert_statements
    result = connection.execute(
             ^^^^^^^^^^^^^^^^^^^
  File "C:\Users\as222\flask_project1\venv\Lib\site-packages\sqlalchemy\engine\base.py", line 1414, in execute
    return meth(
           ^^^^^
  File "C:\Users\as222\flask_project1\venv\Lib\site-packages\sqlalchemy\sql\elements.py", line 485, in _execute_on_connection
    return connection._execute_clauseelement(
           ^^^^^^^^^^^^^^^^^^^^^^^^^^^^^^^^^^
  File "C:\Users\as222\flask_project1\venv\Lib\site-packages\sqlalchemy\engine\base.py", line 1638, in _execute_clauseelement
    ret = self._execute_context(
          ^^^^^^^^^^^^^^^^^^^^^^
  File "C:\Users\as222\flask_project1\venv\Lib\site-packages\sqlalchemy\engine\base.py", line 1842, in _execute_context
    return self._exec_single_context(
           ^^^^^^^^^^^^^^^^^^^^^^^^^^
  File "C:\Users\as222\flask_project1\venv\Lib\site-packages\sqlalchemy\engine\base.py", line 1983, in _exec_single_context
    self._handle_dbapi_exception(
  File "C:\Users\as222\flask_project1\venv\Lib\site-packages\sqlalchemy\engine\base.py", line 2325, in _handle_dbapi_exception
    raise sqlalchemy_exception.with_traceback(exc_info[2]) from e
  File "C:\Users\as222\flask_project1\venv\Lib\site-packages\sqlalchemy\engine\base.py", line 1964, in _exec_single_context
    self.dialect.do_execute(
  File "C:\Users\as222\flask_project1\venv\Lib\site-packages\sqlalchemy\engine\default.py", line 747, in do_execute
    cursor.execute(statement, parameters)
  File "C:\Users\as222\flask_project1\venv\Lib\site-packages\pymysql\cursors.py", line 148, in execute
    result = self._query(query)
             ^^^^^^^^^^^^^^^^^^
  File "C:\Users\as222\flask_project1\venv\Lib\site-packages\pymysql\cursors.py", line 310, in _query
    conn.query(q)
  File "C:\Users\as222\flask_project1\venv\Lib\site-packages\pymysql\connections.py", line 548, in query
    self._affected_rows = self._read_query_result(unbuffered=unbuffered)
                          ^^^^^^^^^^^^^^^^^^^^^^^^^^^^^^^^^^^^^^^^^^^^^^
  File "C:\Users\as222\flask_project1\venv\Lib\site-packages\pymysql\connections.py", line 775, in _read_query_result
    result.read()
  File "C:\Users\as222\flask_project1\venv\Lib\site-packages\pymysql\connections.py", line 1156, in read
    first_packet = self.connection._read_packet()
                   ^^^^^^^^^^^^^^^^^^^^^^^^^^^^^^
  File "C:\Users\as222\flask_project1\venv\Lib\site-packages\pymysql\connections.py", line 725, in _read_packet
    packet.raise_for_error()
  File "C:\Users\as222\flask_project1\venv\Lib\site-packages\pymysql\protocol.py", line 221, in raise_for_error
    err.raise_mysql_exception(self._data)
  File "C:\Users\as222\flask_project1\venv\Lib\site-packages\pymysql\err.py", line 143, in raise_mysql_exception
    raise errorclass(errno, errval)
sqlalchemy.exc.IntegrityError: (pymysql.err.IntegrityError) (1048, "Column 'Photoer_id' cannot be null")
[SQL: INSERT INTO photos (`Name`, `Filename`, `Description`, `Upload_time`, `Photoer_id`) VALUES (%(Name)s, %(Filename)s, %(Description)s, %(Upload_time)s, %(Photoer_id)s)]
[parameters: {'Name': 'ysc30', 'Filename': 'b36614d0-e463-4b35-bef6-a947c80031d512496191_1685565361719719_600581183564192746_o.jpg', 'Description': 'my first ysccamp as a  staff! It was  so unforgetable memories!!!', 'Upload_time': datetime.datetime(2023, 3, 22, 13, 40, 36, 596805), 'Photoer_id': None}]
(Background on this error at: https://sqlalche.me/e/20/gkpj)
2023-03-22 21:46:28,662 - apps - ERROR - Exception on /photo_uploads [POST]
Traceback (most recent call last):
  File "C:\Users\as222\flask_project1\venv\Lib\site-packages\sqlalchemy\engine\base.py", line 1964, in _exec_single_context
    self.dialect.do_execute(
  File "C:\Users\as222\flask_project1\venv\Lib\site-packages\sqlalchemy\engine\default.py", line 747, in do_execute
    cursor.execute(statement, parameters)
  File "C:\Users\as222\flask_project1\venv\Lib\site-packages\pymysql\cursors.py", line 148, in execute
    result = self._query(query)
             ^^^^^^^^^^^^^^^^^^
  File "C:\Users\as222\flask_project1\venv\Lib\site-packages\pymysql\cursors.py", line 310, in _query
    conn.query(q)
  File "C:\Users\as222\flask_project1\venv\Lib\site-packages\pymysql\connections.py", line 548, in query
    self._affected_rows = self._read_query_result(unbuffered=unbuffered)
                          ^^^^^^^^^^^^^^^^^^^^^^^^^^^^^^^^^^^^^^^^^^^^^^
  File "C:\Users\as222\flask_project1\venv\Lib\site-packages\pymysql\connections.py", line 775, in _read_query_result
    result.read()
  File "C:\Users\as222\flask_project1\venv\Lib\site-packages\pymysql\connections.py", line 1156, in read
    first_packet = self.connection._read_packet()
                   ^^^^^^^^^^^^^^^^^^^^^^^^^^^^^^
  File "C:\Users\as222\flask_project1\venv\Lib\site-packages\pymysql\connections.py", line 725, in _read_packet
    packet.raise_for_error()
  File "C:\Users\as222\flask_project1\venv\Lib\site-packages\pymysql\protocol.py", line 221, in raise_for_error
    err.raise_mysql_exception(self._data)
  File "C:\Users\as222\flask_project1\venv\Lib\site-packages\pymysql\err.py", line 143, in raise_mysql_exception
    raise errorclass(errno, errval)
pymysql.err.IntegrityError: (1048, "Column 'Photoer_id' cannot be null")

The above exception was the direct cause of the following exception:

Traceback (most recent call last):
  File "C:\Users\as222\flask_project1\venv\Lib\site-packages\flask\app.py", line 2528, in wsgi_app
    response = self.full_dispatch_request()
               ^^^^^^^^^^^^^^^^^^^^^^^^^^^^
  File "C:\Users\as222\flask_project1\venv\Lib\site-packages\flask\app.py", line 1825, in full_dispatch_request
    rv = self.handle_user_exception(e)
         ^^^^^^^^^^^^^^^^^^^^^^^^^^^^^
  File "C:\Users\as222\flask_project1\venv\Lib\site-packages\flask\app.py", line 1823, in full_dispatch_request
    rv = self.dispatch_request()
         ^^^^^^^^^^^^^^^^^^^^^^^
  File "C:\Users\as222\flask_project1\venv\Lib\site-packages\flask\app.py", line 1799, in dispatch_request
    return self.ensure_sync(self.view_functions[rule.endpoint])(**view_args)
           ^^^^^^^^^^^^^^^^^^^^^^^^^^^^^^^^^^^^^^^^^^^^^^^^^^^^^^^^^^^^^^^^^
  File "C:\Users\as222\flask_project2\router.py", line 140, in upload_photos
    return views.Upload_photo()
           ^^^^^^^^^^^^^^^^^^^^
  File "C:\Users\as222\flask_project2\apps\views\user.py", line 162, in Upload_photo
    db.session.commit()
  File "C:\Users\as222\flask_project1\venv\Lib\site-packages\sqlalchemy\orm\scoping.py", line 538, in commit
    return self._proxied.commit()
           ^^^^^^^^^^^^^^^^^^^^^^
  File "C:\Users\as222\flask_project1\venv\Lib\site-packages\sqlalchemy\orm\session.py", line 1903, in commit
    trans.commit(_to_root=True)
  File "<string>", line 2, in commit
  File "C:\Users\as222\flask_project1\venv\Lib\site-packages\sqlalchemy\orm\state_changes.py", line 137, in _go
    ret_value = fn(self, *arg, **kw)
                ^^^^^^^^^^^^^^^^^^^^
  File "C:\Users\as222\flask_project1\venv\Lib\site-packages\sqlalchemy\orm\session.py", line 1218, in commit
    self._prepare_impl()
  File "<string>", line 2, in _prepare_impl
  File "C:\Users\as222\flask_project1\venv\Lib\site-packages\sqlalchemy\orm\state_changes.py", line 137, in _go
    ret_value = fn(self, *arg, **kw)
                ^^^^^^^^^^^^^^^^^^^^
  File "C:\Users\as222\flask_project1\venv\Lib\site-packages\sqlalchemy\orm\session.py", line 1193, in _prepare_impl
    self.session.flush()
  File "C:\Users\as222\flask_project1\venv\Lib\site-packages\sqlalchemy\orm\session.py", line 4153, in flush
    self._flush(objects)
  File "C:\Users\as222\flask_project1\venv\Lib\site-packages\sqlalchemy\orm\session.py", line 4289, in _flush
    with util.safe_reraise():
  File "C:\Users\as222\flask_project1\venv\Lib\site-packages\sqlalchemy\util\langhelpers.py", line 147, in __exit__
    raise exc_value.with_traceback(exc_tb)
  File "C:\Users\as222\flask_project1\venv\Lib\site-packages\sqlalchemy\orm\session.py", line 4250, in _flush
    flush_context.execute()
  File "C:\Users\as222\flask_project1\venv\Lib\site-packages\sqlalchemy\orm\unitofwork.py", line 467, in execute
    rec.execute(self)
  File "C:\Users\as222\flask_project1\venv\Lib\site-packages\sqlalchemy\orm\unitofwork.py", line 644, in execute
    util.preloaded.orm_persistence.save_obj(
  File "C:\Users\as222\flask_project1\venv\Lib\site-packages\sqlalchemy\orm\persistence.py", line 93, in save_obj
    _emit_insert_statements(
  File "C:\Users\as222\flask_project1\venv\Lib\site-packages\sqlalchemy\orm\persistence.py", line 1188, in _emit_insert_statements
    result = connection.execute(
             ^^^^^^^^^^^^^^^^^^^
  File "C:\Users\as222\flask_project1\venv\Lib\site-packages\sqlalchemy\engine\base.py", line 1414, in execute
    return meth(
           ^^^^^
  File "C:\Users\as222\flask_project1\venv\Lib\site-packages\sqlalchemy\sql\elements.py", line 485, in _execute_on_connection
    return connection._execute_clauseelement(
           ^^^^^^^^^^^^^^^^^^^^^^^^^^^^^^^^^^
  File "C:\Users\as222\flask_project1\venv\Lib\site-packages\sqlalchemy\engine\base.py", line 1638, in _execute_clauseelement
    ret = self._execute_context(
          ^^^^^^^^^^^^^^^^^^^^^^
  File "C:\Users\as222\flask_project1\venv\Lib\site-packages\sqlalchemy\engine\base.py", line 1842, in _execute_context
    return self._exec_single_context(
           ^^^^^^^^^^^^^^^^^^^^^^^^^^
  File "C:\Users\as222\flask_project1\venv\Lib\site-packages\sqlalchemy\engine\base.py", line 1983, in _exec_single_context
    self._handle_dbapi_exception(
  File "C:\Users\as222\flask_project1\venv\Lib\site-packages\sqlalchemy\engine\base.py", line 2325, in _handle_dbapi_exception
    raise sqlalchemy_exception.with_traceback(exc_info[2]) from e
  File "C:\Users\as222\flask_project1\venv\Lib\site-packages\sqlalchemy\engine\base.py", line 1964, in _exec_single_context
    self.dialect.do_execute(
  File "C:\Users\as222\flask_project1\venv\Lib\site-packages\sqlalchemy\engine\default.py", line 747, in do_execute
    cursor.execute(statement, parameters)
  File "C:\Users\as222\flask_project1\venv\Lib\site-packages\pymysql\cursors.py", line 148, in execute
    result = self._query(query)
             ^^^^^^^^^^^^^^^^^^
  File "C:\Users\as222\flask_project1\venv\Lib\site-packages\pymysql\cursors.py", line 310, in _query
    conn.query(q)
  File "C:\Users\as222\flask_project1\venv\Lib\site-packages\pymysql\connections.py", line 548, in query
    self._affected_rows = self._read_query_result(unbuffered=unbuffered)
                          ^^^^^^^^^^^^^^^^^^^^^^^^^^^^^^^^^^^^^^^^^^^^^^
  File "C:\Users\as222\flask_project1\venv\Lib\site-packages\pymysql\connections.py", line 775, in _read_query_result
    result.read()
  File "C:\Users\as222\flask_project1\venv\Lib\site-packages\pymysql\connections.py", line 1156, in read
    first_packet = self.connection._read_packet()
                   ^^^^^^^^^^^^^^^^^^^^^^^^^^^^^^
  File "C:\Users\as222\flask_project1\venv\Lib\site-packages\pymysql\connections.py", line 725, in _read_packet
    packet.raise_for_error()
  File "C:\Users\as222\flask_project1\venv\Lib\site-packages\pymysql\protocol.py", line 221, in raise_for_error
    err.raise_mysql_exception(self._data)
  File "C:\Users\as222\flask_project1\venv\Lib\site-packages\pymysql\err.py", line 143, in raise_mysql_exception
    raise errorclass(errno, errval)
sqlalchemy.exc.IntegrityError: (pymysql.err.IntegrityError) (1048, "Column 'Photoer_id' cannot be null")
[SQL: INSERT INTO photos (`Name`, `Filename`, `Description`, `Upload_time`, `Photoer_id`) VALUES (%(Name)s, %(Filename)s, %(Description)s, %(Upload_time)s, %(Photoer_id)s)]
[parameters: {'Name': 'ysc30', 'Filename': '761390fd-7806-4353-a2b4-d2494558501312496191_1685565361719719_600581183564192746_o.jpg', 'Description': 'my first ysccamp as a  staff! It was  so unforgetable memories!!!', 'Upload_time': datetime.datetime(2023, 3, 22, 13, 46, 28, 658162), 'Photoer_id': None}]
(Background on this error at: https://sqlalche.me/e/20/gkpj)
2023-03-22 21:50:44,477 - apps - ERROR - Exception on /photo [GET]
Traceback (most recent call last):
  File "C:\Users\as222\flask_project1\venv\Lib\site-packages\flask\app.py", line 2528, in wsgi_app
    response = self.full_dispatch_request()
               ^^^^^^^^^^^^^^^^^^^^^^^^^^^^
  File "C:\Users\as222\flask_project1\venv\Lib\site-packages\flask\app.py", line 1825, in full_dispatch_request
    rv = self.handle_user_exception(e)
         ^^^^^^^^^^^^^^^^^^^^^^^^^^^^^
  File "C:\Users\as222\flask_project1\venv\Lib\site-packages\flask\app.py", line 1823, in full_dispatch_request
    rv = self.dispatch_request()
         ^^^^^^^^^^^^^^^^^^^^^^^
  File "C:\Users\as222\flask_project1\venv\Lib\site-packages\flask\app.py", line 1799, in dispatch_request
    return self.ensure_sync(self.view_functions[rule.endpoint])(**view_args)
           ^^^^^^^^^^^^^^^^^^^^^^^^^^^^^^^^^^^^^^^^^^^^^^^^^^^^^^^^^^^^^^^^^
  File "C:\Users\as222\flask_project2\router.py", line 173, in view_photo
    return render_template("user/show_photos.html",photos=photos)
           ^^^^^^^^^^^^^^^^^^^^^^^^^^^^^^^^^^^^^^^^^^^^^^^^^^^^^^
  File "C:\Users\as222\flask_project1\venv\Lib\site-packages\flask\templating.py", line 147, in render_template
    return _render(app, template, context)
           ^^^^^^^^^^^^^^^^^^^^^^^^^^^^^^^
  File "C:\Users\as222\flask_project1\venv\Lib\site-packages\flask\templating.py", line 130, in _render
    rv = template.render(context)
         ^^^^^^^^^^^^^^^^^^^^^^^^
  File "C:\Users\as222\flask_project1\venv\Lib\site-packages\jinja2\environment.py", line 1301, in render
    self.environment.handle_exception()
  File "C:\Users\as222\flask_project1\venv\Lib\site-packages\jinja2\environment.py", line 936, in handle_exception
    raise rewrite_traceback_stack(source=source)
  File "C:\Users\as222\flask_project2\apps\templates\user\show_photos.html", line 1, in top-level template code
    {% extends "user/layout.html" %}
    ^^^^^^^^^^^^^^^^^^^^^^^^^
  File "C:\Users\as222\flask_project2\apps\templates\user\layout.html", line 67, in top-level template code
    {% block body %} {% endblock %}
    ^^^^^^^^^^^^^^^^^^^^^^^^^
  File "C:\Users\as222\flask_project2\apps\templates\user\show_photos.html", line 66, in block 'body'
    <p class="card-text">{{ photo.Photoer.name }}</p>
    ^^^^^^^^^^^^^^^^^^^^^^^^^
  File "C:\Users\as222\flask_project1\venv\Lib\site-packages\jinja2\environment.py", line 485, in getattr
    return getattr(obj, attribute)
           ^^^^^^^^^^^^^^^^^^^^^^^
jinja2.exceptions.UndefinedError: 'apps.models.user.Photos object' has no attribute 'Photoer'
2023-03-22 22:01:46,939 - apps - ERROR - Exception on /photo [GET]
Traceback (most recent call last):
  File "C:\Users\as222\flask_project1\venv\Lib\site-packages\flask\app.py", line 2528, in wsgi_app
    response = self.full_dispatch_request()
               ^^^^^^^^^^^^^^^^^^^^^^^^^^^^
  File "C:\Users\as222\flask_project1\venv\Lib\site-packages\flask\app.py", line 1825, in full_dispatch_request
    rv = self.handle_user_exception(e)
         ^^^^^^^^^^^^^^^^^^^^^^^^^^^^^
  File "C:\Users\as222\flask_project1\venv\Lib\site-packages\flask\app.py", line 1823, in full_dispatch_request
    rv = self.dispatch_request()
         ^^^^^^^^^^^^^^^^^^^^^^^
  File "C:\Users\as222\flask_project1\venv\Lib\site-packages\flask\app.py", line 1799, in dispatch_request
    return self.ensure_sync(self.view_functions[rule.endpoint])(**view_args)
           ^^^^^^^^^^^^^^^^^^^^^^^^^^^^^^^^^^^^^^^^^^^^^^^^^^^^^^^^^^^^^^^^^
  File "C:\Users\as222\flask_project2\router.py", line 173, in view_photo
    return render_template("user/show_photos.html",photos=photos)
           ^^^^^^^^^^^^^^^^^^^^^^^^^^^^^^^^^^^^^^^^^^^^^^^^^^^^^^
  File "C:\Users\as222\flask_project1\venv\Lib\site-packages\flask\templating.py", line 147, in render_template
    return _render(app, template, context)
           ^^^^^^^^^^^^^^^^^^^^^^^^^^^^^^^
  File "C:\Users\as222\flask_project1\venv\Lib\site-packages\flask\templating.py", line 130, in _render
    rv = template.render(context)
         ^^^^^^^^^^^^^^^^^^^^^^^^
  File "C:\Users\as222\flask_project1\venv\Lib\site-packages\jinja2\environment.py", line 1301, in render
    self.environment.handle_exception()
  File "C:\Users\as222\flask_project1\venv\Lib\site-packages\jinja2\environment.py", line 936, in handle_exception
    raise rewrite_traceback_stack(source=source)
  File "C:\Users\as222\flask_project2\apps\templates\user\show_photos.html", line 1, in top-level template code
    {% extends "user/layout.html" %}
    ^^^^^^^^^^^^^^^^^^^^^^^^^
  File "C:\Users\as222\flask_project2\apps\templates\user\layout.html", line 67, in top-level template code
    {% block body %} {% endblock %}
    ^^^^^^^^^^^^^^^^^^^^^^^^^
  File "C:\Users\as222\flask_project2\apps\templates\user\show_photos.html", line 66, in block 'body'
    <p class="card-text">{{ photo.Photoer.name }}</p>
    ^^^^^^^^^^^^^^^^^^^^^^^^^
  File "C:\Users\as222\flask_project1\venv\Lib\site-packages\jinja2\environment.py", line 485, in getattr
    return getattr(obj, attribute)
           ^^^^^^^^^^^^^^^^^^^^^^^
jinja2.exceptions.UndefinedError: 'apps.models.user.Photos object' has no attribute 'Photoer'
2023-03-22 22:06:58,418 - apps - ERROR - Exception on /photo [GET]
Traceback (most recent call last):
  File "C:\Users\as222\flask_project1\venv\Lib\site-packages\flask\app.py", line 2528, in wsgi_app
    response = self.full_dispatch_request()
               ^^^^^^^^^^^^^^^^^^^^^^^^^^^^
  File "C:\Users\as222\flask_project1\venv\Lib\site-packages\flask\app.py", line 1825, in full_dispatch_request
    rv = self.handle_user_exception(e)
         ^^^^^^^^^^^^^^^^^^^^^^^^^^^^^
  File "C:\Users\as222\flask_project1\venv\Lib\site-packages\flask\app.py", line 1823, in full_dispatch_request
    rv = self.dispatch_request()
         ^^^^^^^^^^^^^^^^^^^^^^^
  File "C:\Users\as222\flask_project1\venv\Lib\site-packages\flask\app.py", line 1799, in dispatch_request
    return self.ensure_sync(self.view_functions[rule.endpoint])(**view_args)
           ^^^^^^^^^^^^^^^^^^^^^^^^^^^^^^^^^^^^^^^^^^^^^^^^^^^^^^^^^^^^^^^^^
  File "C:\Users\as222\flask_project2\router.py", line 173, in view_photo
    return render_template("user/show_photos.html",photos=photos)
           ^^^^^^^^^^^^^^^^^^^^^^^^^^^^^^^^^^^^^^^^^^^^^^^^^^^^^^
  File "C:\Users\as222\flask_project1\venv\Lib\site-packages\flask\templating.py", line 147, in render_template
    return _render(app, template, context)
           ^^^^^^^^^^^^^^^^^^^^^^^^^^^^^^^
  File "C:\Users\as222\flask_project1\venv\Lib\site-packages\flask\templating.py", line 130, in _render
    rv = template.render(context)
         ^^^^^^^^^^^^^^^^^^^^^^^^
  File "C:\Users\as222\flask_project1\venv\Lib\site-packages\jinja2\environment.py", line 1301, in render
    self.environment.handle_exception()
  File "C:\Users\as222\flask_project1\venv\Lib\site-packages\jinja2\environment.py", line 936, in handle_exception
    raise rewrite_traceback_stack(source=source)
  File "C:\Users\as222\flask_project2\apps\templates\user\show_photos.html", line 1, in top-level template code
    {% extends "user/layout.html" %}
    ^^^^^^^^^^^^^^^^^^^^^^^^^
  File "C:\Users\as222\flask_project2\apps\templates\user\layout.html", line 67, in top-level template code
    {% block body %} {% endblock %}
    ^^^^^^^^^^^^^^^^^^^^^^^^^
  File "C:\Users\as222\flask_project2\apps\templates\user\show_photos.html", line 66, in block 'body'
    <p class="card-text">Author:{{ photo.photoer.name }}</p>
    ^^^^^^^^^^^^^^^^^^^^^^^^^
  File "C:\Users\as222\flask_project1\venv\Lib\site-packages\jinja2\environment.py", line 485, in getattr
    return getattr(obj, attribute)
           ^^^^^^^^^^^^^^^^^^^^^^^
jinja2.exceptions.UndefinedError: 'apps.models.user.Photos object' has no attribute 'photoer'
2023-03-23 19:38:07,522 - apps - ERROR - Exception on /photo/delete/8 [GET]
Traceback (most recent call last):
  File "C:\Users\as222\flask_project1\venv\Lib\site-packages\flask\app.py", line 2528, in wsgi_app
    response = self.full_dispatch_request()
               ^^^^^^^^^^^^^^^^^^^^^^^^^^^^
  File "C:\Users\as222\flask_project1\venv\Lib\site-packages\flask\app.py", line 1825, in full_dispatch_request
    rv = self.handle_user_exception(e)
         ^^^^^^^^^^^^^^^^^^^^^^^^^^^^^
  File "C:\Users\as222\flask_project1\venv\Lib\site-packages\flask\app.py", line 1823, in full_dispatch_request
    rv = self.dispatch_request()
         ^^^^^^^^^^^^^^^^^^^^^^^
  File "C:\Users\as222\flask_project1\venv\Lib\site-packages\flask\app.py", line 1799, in dispatch_request
    return self.ensure_sync(self.view_functions[rule.endpoint])(**view_args)
           ^^^^^^^^^^^^^^^^^^^^^^^^^^^^^^^^^^^^^^^^^^^^^^^^^^^^^^^^^^^^^^^^^
  File "C:\Users\as222\flask_project2\router.py", line 164, in photo_delete_id
    return views.Delete_photo_id(id)
           ^^^^^^^^^^^^^^^^^^^^^^^^^
  File "C:\Users\as222\flask_project2\apps\views\user.py", line 170, in Delete_photo_id
    if current_user.id==photo_to_delete.Photoer.id:
                        ^^^^^^^^^^^^^^^^^^^^^^^
AttributeError: 'Photos' object has no attribute 'Photoer'
